WARNING:root:Setting up a new session...
Traceback (most recent call last):
  File "/home/home1/sy189/.local/lib/python3.6/site-packages/urllib3/connection.py", line 157, in _new_conn
    (self._dns_host, self.port), self.timeout, **extra_kw
  File "/home/home1/sy189/.local/lib/python3.6/site-packages/urllib3/util/connection.py", line 84, in create_connection
    raise err
  File "/home/home1/sy189/.local/lib/python3.6/site-packages/urllib3/util/connection.py", line 74, in create_connection
    sock.connect(sa)
ConnectionRefusedError: [Errno 111] Connection refused

During handling of the above exception, another exception occurred:

Traceback (most recent call last):
  File "/home/home1/sy189/.local/lib/python3.6/site-packages/urllib3/connectionpool.py", line 672, in urlopen
    chunked=chunked,
  File "/home/home1/sy189/.local/lib/python3.6/site-packages/urllib3/connectionpool.py", line 387, in _make_request
    conn.request(method, url, **httplib_request_kw)
  File "/usr/lib/python3.6/http/client.py", line 1254, in request
    self._send_request(method, url, body, headers, encode_chunked)
  File "/usr/lib/python3.6/http/client.py", line 1300, in _send_request
    self.endheaders(body, encode_chunked=encode_chunked)
  File "/usr/lib/python3.6/http/client.py", line 1249, in endheaders
    self._send_output(message_body, encode_chunked=encode_chunked)
  File "/usr/lib/python3.6/http/client.py", line 1036, in _send_output
    self.send(msg)
  File "/usr/lib/python3.6/http/client.py", line 974, in send
    self.connect()
  File "/home/home1/sy189/.local/lib/python3.6/site-packages/urllib3/connection.py", line 184, in connect
    conn = self._new_conn()
  File "/home/home1/sy189/.local/lib/python3.6/site-packages/urllib3/connection.py", line 169, in _new_conn
    self, "Failed to establish a new connection: %s" % e
urllib3.exceptions.NewConnectionError: <urllib3.connection.HTTPConnection object at 0x14ba78c4be80>: Failed to establish a new connection: [Errno 111] Connection refused

During handling of the above exception, another exception occurred:

Traceback (most recent call last):
  File "/home/home1/sy189/.local/lib/python3.6/site-packages/requests/adapters.py", line 449, in send
    timeout=timeout
  File "/home/home1/sy189/.local/lib/python3.6/site-packages/urllib3/connectionpool.py", line 720, in urlopen
    method, url, error=e, _pool=self, _stacktrace=sys.exc_info()[2]
  File "/home/home1/sy189/.local/lib/python3.6/site-packages/urllib3/util/retry.py", line 436, in increment
    raise MaxRetryError(_pool, url, error or ResponseError(cause))
urllib3.exceptions.MaxRetryError: HTTPConnectionPool(host='localhost', port=8888): Max retries exceeded with url: /env/deeplab.mobilenet.vegas.bottleneck-bn.adversarial (Caused by NewConnectionError('<urllib3.connection.HTTPConnection object at 0x14ba78c4be80>: Failed to establish a new connection: [Errno 111] Connection refused',))

During handling of the above exception, another exception occurred:

Traceback (most recent call last):
  File "/home/home1/sy189/.local/lib/python3.6/site-packages/visdom/__init__.py", line 548, in _send
    data=json.dumps(msg),
  File "/home/home1/sy189/.local/lib/python3.6/site-packages/requests/sessions.py", line 581, in post
    return self.request('POST', url, data=data, json=json, **kwargs)
  File "/home/home1/sy189/.local/lib/python3.6/site-packages/requests/sessions.py", line 533, in request
    resp = self.send(prep, **send_kwargs)
  File "/home/home1/sy189/.local/lib/python3.6/site-packages/requests/sessions.py", line 646, in send
    r = adapter.send(request, **kwargs)
  File "/home/home1/sy189/.local/lib/python3.6/site-packages/requests/adapters.py", line 516, in send
    raise ConnectionError(e, request=request)
requests.exceptions.ConnectionError: HTTPConnectionPool(host='localhost', port=8888): Max retries exceeded with url: /env/deeplab.mobilenet.vegas.bottleneck-bn.adversarial (Caused by NewConnectionError('<urllib3.connection.HTTPConnection object at 0x14ba78c4be80>: Failed to establish a new connection: [Errno 111] Connection refused',))
ERROR:visdom:[Errno 111] Connection refused
  0%|          | 0/133 [00:00<?, ?it/s]Traceback (most recent call last):
  File "/home/home1/sy189/.local/lib/python3.6/site-packages/urllib3/connection.py", line 157, in _new_conn
    (self._dns_host, self.port), self.timeout, **extra_kw
  File "/home/home1/sy189/.local/lib/python3.6/site-packages/urllib3/util/connection.py", line 84, in create_connection
    raise err
  File "/home/home1/sy189/.local/lib/python3.6/site-packages/urllib3/util/connection.py", line 74, in create_connection
    sock.connect(sa)
ConnectionRefusedError: [Errno 111] Connection refused

During handling of the above exception, another exception occurred:

Traceback (most recent call last):
  File "/home/home1/sy189/.local/lib/python3.6/site-packages/urllib3/connectionpool.py", line 672, in urlopen
    chunked=chunked,
  File "/home/home1/sy189/.local/lib/python3.6/site-packages/urllib3/connectionpool.py", line 387, in _make_request
    conn.request(method, url, **httplib_request_kw)
  File "/usr/lib/python3.6/http/client.py", line 1254, in request
    self._send_request(method, url, body, headers, encode_chunked)
  File "/usr/lib/python3.6/http/client.py", line 1300, in _send_request
    self.endheaders(body, encode_chunked=encode_chunked)
  File "/usr/lib/python3.6/http/client.py", line 1249, in endheaders
    self._send_output(message_body, encode_chunked=encode_chunked)
  File "/usr/lib/python3.6/http/client.py", line 1036, in _send_output
    self.send(msg)
  File "/usr/lib/python3.6/http/client.py", line 974, in send
    self.connect()
  File "/home/home1/sy189/.local/lib/python3.6/site-packages/urllib3/connection.py", line 184, in connect
    conn = self._new_conn()
  File "/home/home1/sy189/.local/lib/python3.6/site-packages/urllib3/connection.py", line 169, in _new_conn
    self, "Failed to establish a new connection: %s" % e
urllib3.exceptions.NewConnectionError: <urllib3.connection.HTTPConnection object at 0x14ba70e92a20>: Failed to establish a new connection: [Errno 111] Connection refused

During handling of the above exception, another exception occurred:

Traceback (most recent call last):
  File "/home/home1/sy189/.local/lib/python3.6/site-packages/requests/adapters.py", line 449, in send
    timeout=timeout
  File "/home/home1/sy189/.local/lib/python3.6/site-packages/urllib3/connectionpool.py", line 720, in urlopen
    method, url, error=e, _pool=self, _stacktrace=sys.exc_info()[2]
  File "/home/home1/sy189/.local/lib/python3.6/site-packages/urllib3/util/retry.py", line 436, in increment
    raise MaxRetryError(_pool, url, error or ResponseError(cause))
urllib3.exceptions.MaxRetryError: HTTPConnectionPool(host='localhost', port=8888): Max retries exceeded with url: /events (Caused by NewConnectionError('<urllib3.connection.HTTPConnection object at 0x14ba70e92a20>: Failed to establish a new connection: [Errno 111] Connection refused',))

During handling of the above exception, another exception occurred:

Traceback (most recent call last):
  File "/home/home1/sy189/.local/lib/python3.6/site-packages/visdom/__init__.py", line 548, in _send
    data=json.dumps(msg),
  File "/home/home1/sy189/.local/lib/python3.6/site-packages/requests/sessions.py", line 581, in post
    return self.request('POST', url, data=data, json=json, **kwargs)
  File "/home/home1/sy189/.local/lib/python3.6/site-packages/requests/sessions.py", line 533, in request
    resp = self.send(prep, **send_kwargs)
  File "/home/home1/sy189/.local/lib/python3.6/site-packages/requests/sessions.py", line 646, in send
    r = adapter.send(request, **kwargs)
  File "/home/home1/sy189/.local/lib/python3.6/site-packages/requests/adapters.py", line 516, in send
    raise ConnectionError(e, request=request)
requests.exceptions.ConnectionError: HTTPConnectionPool(host='localhost', port=8888): Max retries exceeded with url: /events (Caused by NewConnectionError('<urllib3.connection.HTTPConnection object at 0x14ba70e92a20>: Failed to establish a new connection: [Errno 111] Connection refused',))
/home/home1/sy189/.local/lib/python3.6/site-packages/torch/nn/_reduction.py:43: UserWarning: size_average and reduce args will be deprecated, please use reduction='mean' instead.
  warnings.warn(warning.format(ret))
train.py:143: UserWarning: Implicit dimension choice for softmax has been deprecated. Change the call to include dim=X as an argument.
  D_out = self.D(prob_2_entropy(F.softmax(B_output)))
train.py:155: UserWarning: Implicit dimension choice for softmax has been deprecated. Change the call to include dim=X as an argument.
  D_source = self.D(prob_2_entropy(F.softmax(A_output_detach)))
train.py:160: UserWarning: Implicit dimension choice for softmax has been deprecated. Change the call to include dim=X as an argument.
  D_target = self.D(prob_2_entropy(F.softmax(B_output_detach)))
Train loss: 0.043:   0%|          | 0/133 [00:20<?, ?it/s]Train loss: 0.043:   1%|          | 1/133 [00:20<46:09, 20.98s/it]Traceback (most recent call last):
  File "/home/home1/sy189/.local/lib/python3.6/site-packages/urllib3/connection.py", line 157, in _new_conn
    (self._dns_host, self.port), self.timeout, **extra_kw
  File "/home/home1/sy189/.local/lib/python3.6/site-packages/urllib3/util/connection.py", line 84, in create_connection
    raise err
  File "/home/home1/sy189/.local/lib/python3.6/site-packages/urllib3/util/connection.py", line 74, in create_connection
    sock.connect(sa)
ConnectionRefusedError: [Errno 111] Connection refused

During handling of the above exception, another exception occurred:

Traceback (most recent call last):
  File "/home/home1/sy189/.local/lib/python3.6/site-packages/urllib3/connectionpool.py", line 672, in urlopen
    chunked=chunked,
  File "/home/home1/sy189/.local/lib/python3.6/site-packages/urllib3/connectionpool.py", line 387, in _make_request
    conn.request(method, url, **httplib_request_kw)
  File "/usr/lib/python3.6/http/client.py", line 1254, in request
    self._send_request(method, url, body, headers, encode_chunked)
  File "/usr/lib/python3.6/http/client.py", line 1300, in _send_request
    self.endheaders(body, encode_chunked=encode_chunked)
  File "/usr/lib/python3.6/http/client.py", line 1249, in endheaders
    self._send_output(message_body, encode_chunked=encode_chunked)
  File "/usr/lib/python3.6/http/client.py", line 1036, in _send_output
    self.send(msg)
  File "/usr/lib/python3.6/http/client.py", line 974, in send
    self.connect()
  File "/home/home1/sy189/.local/lib/python3.6/site-packages/urllib3/connection.py", line 184, in connect
    conn = self._new_conn()
  File "/home/home1/sy189/.local/lib/python3.6/site-packages/urllib3/connection.py", line 169, in _new_conn
    self, "Failed to establish a new connection: %s" % e
urllib3.exceptions.NewConnectionError: <urllib3.connection.HTTPConnection object at 0x14ba70ea6400>: Failed to establish a new connection: [Errno 111] Connection refused

During handling of the above exception, another exception occurred:

Traceback (most recent call last):
  File "/home/home1/sy189/.local/lib/python3.6/site-packages/requests/adapters.py", line 449, in send
    timeout=timeout
  File "/home/home1/sy189/.local/lib/python3.6/site-packages/urllib3/connectionpool.py", line 720, in urlopen
    method, url, error=e, _pool=self, _stacktrace=sys.exc_info()[2]
  File "/home/home1/sy189/.local/lib/python3.6/site-packages/urllib3/util/retry.py", line 436, in increment
    raise MaxRetryError(_pool, url, error or ResponseError(cause))
urllib3.exceptions.MaxRetryError: HTTPConnectionPool(host='localhost', port=8888): Max retries exceeded with url: /events (Caused by NewConnectionError('<urllib3.connection.HTTPConnection object at 0x14ba70ea6400>: Failed to establish a new connection: [Errno 111] Connection refused',))

During handling of the above exception, another exception occurred:

Traceback (most recent call last):
  File "/home/home1/sy189/.local/lib/python3.6/site-packages/visdom/__init__.py", line 548, in _send
    data=json.dumps(msg),
  File "/home/home1/sy189/.local/lib/python3.6/site-packages/requests/sessions.py", line 581, in post
    return self.request('POST', url, data=data, json=json, **kwargs)
  File "/home/home1/sy189/.local/lib/python3.6/site-packages/requests/sessions.py", line 533, in request
    resp = self.send(prep, **send_kwargs)
  File "/home/home1/sy189/.local/lib/python3.6/site-packages/requests/sessions.py", line 646, in send
    r = adapter.send(request, **kwargs)
  File "/home/home1/sy189/.local/lib/python3.6/site-packages/requests/adapters.py", line 516, in send
    raise ConnectionError(e, request=request)
requests.exceptions.ConnectionError: HTTPConnectionPool(host='localhost', port=8888): Max retries exceeded with url: /events (Caused by NewConnectionError('<urllib3.connection.HTTPConnection object at 0x14ba70ea6400>: Failed to establish a new connection: [Errno 111] Connection refused',))
Train loss: 0.044:   1%|          | 1/133 [00:22<46:09, 20.98s/it]Train loss: 0.044:   2%|▏         | 2/133 [00:22<33:00, 15.12s/it]Traceback (most recent call last):
  File "/home/home1/sy189/.local/lib/python3.6/site-packages/urllib3/connection.py", line 157, in _new_conn
    (self._dns_host, self.port), self.timeout, **extra_kw
  File "/home/home1/sy189/.local/lib/python3.6/site-packages/urllib3/util/connection.py", line 84, in create_connection
    raise err
  File "/home/home1/sy189/.local/lib/python3.6/site-packages/urllib3/util/connection.py", line 74, in create_connection
    sock.connect(sa)
ConnectionRefusedError: [Errno 111] Connection refused

During handling of the above exception, another exception occurred:

Traceback (most recent call last):
  File "/home/home1/sy189/.local/lib/python3.6/site-packages/urllib3/connectionpool.py", line 672, in urlopen
    chunked=chunked,
  File "/home/home1/sy189/.local/lib/python3.6/site-packages/urllib3/connectionpool.py", line 387, in _make_request
    conn.request(method, url, **httplib_request_kw)
  File "/usr/lib/python3.6/http/client.py", line 1254, in request
    self._send_request(method, url, body, headers, encode_chunked)
  File "/usr/lib/python3.6/http/client.py", line 1300, in _send_request
    self.endheaders(body, encode_chunked=encode_chunked)
  File "/usr/lib/python3.6/http/client.py", line 1249, in endheaders
    self._send_output(message_body, encode_chunked=encode_chunked)
  File "/usr/lib/python3.6/http/client.py", line 1036, in _send_output
    self.send(msg)
  File "/usr/lib/python3.6/http/client.py", line 974, in send
    self.connect()
  File "/home/home1/sy189/.local/lib/python3.6/site-packages/urllib3/connection.py", line 184, in connect
    conn = self._new_conn()
  File "/home/home1/sy189/.local/lib/python3.6/site-packages/urllib3/connection.py", line 169, in _new_conn
    self, "Failed to establish a new connection: %s" % e
urllib3.exceptions.NewConnectionError: <urllib3.connection.HTTPConnection object at 0x14ba70ea60f0>: Failed to establish a new connection: [Errno 111] Connection refused

During handling of the above exception, another exception occurred:

Traceback (most recent call last):
  File "/home/home1/sy189/.local/lib/python3.6/site-packages/requests/adapters.py", line 449, in send
    timeout=timeout
  File "/home/home1/sy189/.local/lib/python3.6/site-packages/urllib3/connectionpool.py", line 720, in urlopen
    method, url, error=e, _pool=self, _stacktrace=sys.exc_info()[2]
  File "/home/home1/sy189/.local/lib/python3.6/site-packages/urllib3/util/retry.py", line 436, in increment
    raise MaxRetryError(_pool, url, error or ResponseError(cause))
urllib3.exceptions.MaxRetryError: HTTPConnectionPool(host='localhost', port=8888): Max retries exceeded with url: /events (Caused by NewConnectionError('<urllib3.connection.HTTPConnection object at 0x14ba70ea60f0>: Failed to establish a new connection: [Errno 111] Connection refused',))

During handling of the above exception, another exception occurred:

Traceback (most recent call last):
  File "/home/home1/sy189/.local/lib/python3.6/site-packages/visdom/__init__.py", line 548, in _send
    data=json.dumps(msg),
  File "/home/home1/sy189/.local/lib/python3.6/site-packages/requests/sessions.py", line 581, in post
    return self.request('POST', url, data=data, json=json, **kwargs)
  File "/home/home1/sy189/.local/lib/python3.6/site-packages/requests/sessions.py", line 533, in request
    resp = self.send(prep, **send_kwargs)
  File "/home/home1/sy189/.local/lib/python3.6/site-packages/requests/sessions.py", line 646, in send
    r = adapter.send(request, **kwargs)
  File "/home/home1/sy189/.local/lib/python3.6/site-packages/requests/adapters.py", line 516, in send
    raise ConnectionError(e, request=request)
requests.exceptions.ConnectionError: HTTPConnectionPool(host='localhost', port=8888): Max retries exceeded with url: /events (Caused by NewConnectionError('<urllib3.connection.HTTPConnection object at 0x14ba70ea60f0>: Failed to establish a new connection: [Errno 111] Connection refused',))
Train loss: 0.044:   2%|▏         | 2/133 [00:23<33:00, 15.12s/it]Train loss: 0.044:   2%|▏         | 3/133 [00:23<23:52, 11.02s/it]Traceback (most recent call last):
  File "/home/home1/sy189/.local/lib/python3.6/site-packages/urllib3/connection.py", line 157, in _new_conn
    (self._dns_host, self.port), self.timeout, **extra_kw
  File "/home/home1/sy189/.local/lib/python3.6/site-packages/urllib3/util/connection.py", line 84, in create_connection
    raise err
  File "/home/home1/sy189/.local/lib/python3.6/site-packages/urllib3/util/connection.py", line 74, in create_connection
    sock.connect(sa)
ConnectionRefusedError: [Errno 111] Connection refused

During handling of the above exception, another exception occurred:

Traceback (most recent call last):
  File "/home/home1/sy189/.local/lib/python3.6/site-packages/urllib3/connectionpool.py", line 672, in urlopen
    chunked=chunked,
  File "/home/home1/sy189/.local/lib/python3.6/site-packages/urllib3/connectionpool.py", line 387, in _make_request
    conn.request(method, url, **httplib_request_kw)
  File "/usr/lib/python3.6/http/client.py", line 1254, in request
    self._send_request(method, url, body, headers, encode_chunked)
  File "/usr/lib/python3.6/http/client.py", line 1300, in _send_request
    self.endheaders(body, encode_chunked=encode_chunked)
  File "/usr/lib/python3.6/http/client.py", line 1249, in endheaders
    self._send_output(message_body, encode_chunked=encode_chunked)
  File "/usr/lib/python3.6/http/client.py", line 1036, in _send_output
    self.send(msg)
  File "/usr/lib/python3.6/http/client.py", line 974, in send
    self.connect()
  File "/home/home1/sy189/.local/lib/python3.6/site-packages/urllib3/connection.py", line 184, in connect
    conn = self._new_conn()
  File "/home/home1/sy189/.local/lib/python3.6/site-packages/urllib3/connection.py", line 169, in _new_conn
    self, "Failed to establish a new connection: %s" % e
urllib3.exceptions.NewConnectionError: <urllib3.connection.HTTPConnection object at 0x14ba70ea6358>: Failed to establish a new connection: [Errno 111] Connection refused

During handling of the above exception, another exception occurred:

Traceback (most recent call last):
  File "/home/home1/sy189/.local/lib/python3.6/site-packages/requests/adapters.py", line 449, in send
    timeout=timeout
  File "/home/home1/sy189/.local/lib/python3.6/site-packages/urllib3/connectionpool.py", line 720, in urlopen
    method, url, error=e, _pool=self, _stacktrace=sys.exc_info()[2]
  File "/home/home1/sy189/.local/lib/python3.6/site-packages/urllib3/util/retry.py", line 436, in increment
    raise MaxRetryError(_pool, url, error or ResponseError(cause))
urllib3.exceptions.MaxRetryError: HTTPConnectionPool(host='localhost', port=8888): Max retries exceeded with url: /events (Caused by NewConnectionError('<urllib3.connection.HTTPConnection object at 0x14ba70ea6358>: Failed to establish a new connection: [Errno 111] Connection refused',))

During handling of the above exception, another exception occurred:

Traceback (most recent call last):
  File "/home/home1/sy189/.local/lib/python3.6/site-packages/visdom/__init__.py", line 548, in _send
    data=json.dumps(msg),
  File "/home/home1/sy189/.local/lib/python3.6/site-packages/requests/sessions.py", line 581, in post
    return self.request('POST', url, data=data, json=json, **kwargs)
  File "/home/home1/sy189/.local/lib/python3.6/site-packages/requests/sessions.py", line 533, in request
    resp = self.send(prep, **send_kwargs)
  File "/home/home1/sy189/.local/lib/python3.6/site-packages/requests/sessions.py", line 646, in send
    r = adapter.send(request, **kwargs)
  File "/home/home1/sy189/.local/lib/python3.6/site-packages/requests/adapters.py", line 516, in send
    raise ConnectionError(e, request=request)
requests.exceptions.ConnectionError: HTTPConnectionPool(host='localhost', port=8888): Max retries exceeded with url: /events (Caused by NewConnectionError('<urllib3.connection.HTTPConnection object at 0x14ba70ea6358>: Failed to establish a new connection: [Errno 111] Connection refused',))
Train loss: 0.044:   2%|▏         | 3/133 [00:25<23:52, 11.02s/it]Train loss: 0.044:   3%|▎         | 4/133 [00:25<17:28,  8.13s/it]Traceback (most recent call last):
  File "/home/home1/sy189/.local/lib/python3.6/site-packages/urllib3/connection.py", line 157, in _new_conn
    (self._dns_host, self.port), self.timeout, **extra_kw
  File "/home/home1/sy189/.local/lib/python3.6/site-packages/urllib3/util/connection.py", line 84, in create_connection
    raise err
  File "/home/home1/sy189/.local/lib/python3.6/site-packages/urllib3/util/connection.py", line 74, in create_connection
    sock.connect(sa)
ConnectionRefusedError: [Errno 111] Connection refused

During handling of the above exception, another exception occurred:

Traceback (most recent call last):
  File "/home/home1/sy189/.local/lib/python3.6/site-packages/urllib3/connectionpool.py", line 672, in urlopen
    chunked=chunked,
  File "/home/home1/sy189/.local/lib/python3.6/site-packages/urllib3/connectionpool.py", line 387, in _make_request
    conn.request(method, url, **httplib_request_kw)
  File "/usr/lib/python3.6/http/client.py", line 1254, in request
    self._send_request(method, url, body, headers, encode_chunked)
  File "/usr/lib/python3.6/http/client.py", line 1300, in _send_request
    self.endheaders(body, encode_chunked=encode_chunked)
  File "/usr/lib/python3.6/http/client.py", line 1249, in endheaders
    self._send_output(message_body, encode_chunked=encode_chunked)
  File "/usr/lib/python3.6/http/client.py", line 1036, in _send_output
    self.send(msg)
  File "/usr/lib/python3.6/http/client.py", line 974, in send
    self.connect()
  File "/home/home1/sy189/.local/lib/python3.6/site-packages/urllib3/connection.py", line 184, in connect
    conn = self._new_conn()
  File "/home/home1/sy189/.local/lib/python3.6/site-packages/urllib3/connection.py", line 169, in _new_conn
    self, "Failed to establish a new connection: %s" % e
urllib3.exceptions.NewConnectionError: <urllib3.connection.HTTPConnection object at 0x14ba70e336d8>: Failed to establish a new connection: [Errno 111] Connection refused

During handling of the above exception, another exception occurred:

Traceback (most recent call last):
  File "/home/home1/sy189/.local/lib/python3.6/site-packages/requests/adapters.py", line 449, in send
    timeout=timeout
  File "/home/home1/sy189/.local/lib/python3.6/site-packages/urllib3/connectionpool.py", line 720, in urlopen
    method, url, error=e, _pool=self, _stacktrace=sys.exc_info()[2]
  File "/home/home1/sy189/.local/lib/python3.6/site-packages/urllib3/util/retry.py", line 436, in increment
    raise MaxRetryError(_pool, url, error or ResponseError(cause))
urllib3.exceptions.MaxRetryError: HTTPConnectionPool(host='localhost', port=8888): Max retries exceeded with url: /events (Caused by NewConnectionError('<urllib3.connection.HTTPConnection object at 0x14ba70e336d8>: Failed to establish a new connection: [Errno 111] Connection refused',))

During handling of the above exception, another exception occurred:

Traceback (most recent call last):
  File "/home/home1/sy189/.local/lib/python3.6/site-packages/visdom/__init__.py", line 548, in _send
    data=json.dumps(msg),
  File "/home/home1/sy189/.local/lib/python3.6/site-packages/requests/sessions.py", line 581, in post
    return self.request('POST', url, data=data, json=json, **kwargs)
  File "/home/home1/sy189/.local/lib/python3.6/site-packages/requests/sessions.py", line 533, in request
    resp = self.send(prep, **send_kwargs)
  File "/home/home1/sy189/.local/lib/python3.6/site-packages/requests/sessions.py", line 646, in send
    r = adapter.send(request, **kwargs)
  File "/home/home1/sy189/.local/lib/python3.6/site-packages/requests/adapters.py", line 516, in send
    raise ConnectionError(e, request=request)
requests.exceptions.ConnectionError: HTTPConnectionPool(host='localhost', port=8888): Max retries exceeded with url: /events (Caused by NewConnectionError('<urllib3.connection.HTTPConnection object at 0x14ba70e336d8>: Failed to establish a new connection: [Errno 111] Connection refused',))
Train loss: 0.044:   3%|▎         | 4/133 [00:26<17:28,  8.13s/it]Train loss: 0.044:   4%|▍         | 5/133 [00:26<13:06,  6.15s/it]Traceback (most recent call last):
  File "/home/home1/sy189/.local/lib/python3.6/site-packages/urllib3/connection.py", line 157, in _new_conn
    (self._dns_host, self.port), self.timeout, **extra_kw
  File "/home/home1/sy189/.local/lib/python3.6/site-packages/urllib3/util/connection.py", line 84, in create_connection
    raise err
  File "/home/home1/sy189/.local/lib/python3.6/site-packages/urllib3/util/connection.py", line 74, in create_connection
    sock.connect(sa)
ConnectionRefusedError: [Errno 111] Connection refused

During handling of the above exception, another exception occurred:

Traceback (most recent call last):
  File "/home/home1/sy189/.local/lib/python3.6/site-packages/urllib3/connectionpool.py", line 672, in urlopen
    chunked=chunked,
  File "/home/home1/sy189/.local/lib/python3.6/site-packages/urllib3/connectionpool.py", line 387, in _make_request
    conn.request(method, url, **httplib_request_kw)
  File "/usr/lib/python3.6/http/client.py", line 1254, in request
    self._send_request(method, url, body, headers, encode_chunked)
  File "/usr/lib/python3.6/http/client.py", line 1300, in _send_request
    self.endheaders(body, encode_chunked=encode_chunked)
  File "/usr/lib/python3.6/http/client.py", line 1249, in endheaders
    self._send_output(message_body, encode_chunked=encode_chunked)
  File "/usr/lib/python3.6/http/client.py", line 1036, in _send_output
    self.send(msg)
  File "/usr/lib/python3.6/http/client.py", line 974, in send
    self.connect()
  File "/home/home1/sy189/.local/lib/python3.6/site-packages/urllib3/connection.py", line 184, in connect
    conn = self._new_conn()
  File "/home/home1/sy189/.local/lib/python3.6/site-packages/urllib3/connection.py", line 169, in _new_conn
    self, "Failed to establish a new connection: %s" % e
urllib3.exceptions.NewConnectionError: <urllib3.connection.HTTPConnection object at 0x14ba70e924e0>: Failed to establish a new connection: [Errno 111] Connection refused

During handling of the above exception, another exception occurred:

Traceback (most recent call last):
  File "/home/home1/sy189/.local/lib/python3.6/site-packages/requests/adapters.py", line 449, in send
    timeout=timeout
  File "/home/home1/sy189/.local/lib/python3.6/site-packages/urllib3/connectionpool.py", line 720, in urlopen
    method, url, error=e, _pool=self, _stacktrace=sys.exc_info()[2]
  File "/home/home1/sy189/.local/lib/python3.6/site-packages/urllib3/util/retry.py", line 436, in increment
    raise MaxRetryError(_pool, url, error or ResponseError(cause))
urllib3.exceptions.MaxRetryError: HTTPConnectionPool(host='localhost', port=8888): Max retries exceeded with url: /events (Caused by NewConnectionError('<urllib3.connection.HTTPConnection object at 0x14ba70e924e0>: Failed to establish a new connection: [Errno 111] Connection refused',))

During handling of the above exception, another exception occurred:

Traceback (most recent call last):
  File "/home/home1/sy189/.local/lib/python3.6/site-packages/visdom/__init__.py", line 548, in _send
    data=json.dumps(msg),
  File "/home/home1/sy189/.local/lib/python3.6/site-packages/requests/sessions.py", line 581, in post
    return self.request('POST', url, data=data, json=json, **kwargs)
  File "/home/home1/sy189/.local/lib/python3.6/site-packages/requests/sessions.py", line 533, in request
    resp = self.send(prep, **send_kwargs)
  File "/home/home1/sy189/.local/lib/python3.6/site-packages/requests/sessions.py", line 646, in send
    r = adapter.send(request, **kwargs)
  File "/home/home1/sy189/.local/lib/python3.6/site-packages/requests/adapters.py", line 516, in send
    raise ConnectionError(e, request=request)
requests.exceptions.ConnectionError: HTTPConnectionPool(host='localhost', port=8888): Max retries exceeded with url: /events (Caused by NewConnectionError('<urllib3.connection.HTTPConnection object at 0x14ba70e924e0>: Failed to establish a new connection: [Errno 111] Connection refused',))
Train loss: 0.044:   4%|▍         | 5/133 [00:28<13:06,  6.15s/it]Train loss: 0.044:   5%|▍         | 6/133 [00:28<09:58,  4.71s/it]Traceback (most recent call last):
  File "/home/home1/sy189/.local/lib/python3.6/site-packages/urllib3/connection.py", line 157, in _new_conn
    (self._dns_host, self.port), self.timeout, **extra_kw
  File "/home/home1/sy189/.local/lib/python3.6/site-packages/urllib3/util/connection.py", line 84, in create_connection
    raise err
  File "/home/home1/sy189/.local/lib/python3.6/site-packages/urllib3/util/connection.py", line 74, in create_connection
    sock.connect(sa)
ConnectionRefusedError: [Errno 111] Connection refused

During handling of the above exception, another exception occurred:

Traceback (most recent call last):
  File "/home/home1/sy189/.local/lib/python3.6/site-packages/urllib3/connectionpool.py", line 672, in urlopen
    chunked=chunked,
  File "/home/home1/sy189/.local/lib/python3.6/site-packages/urllib3/connectionpool.py", line 387, in _make_request
    conn.request(method, url, **httplib_request_kw)
  File "/usr/lib/python3.6/http/client.py", line 1254, in request
    self._send_request(method, url, body, headers, encode_chunked)
  File "/usr/lib/python3.6/http/client.py", line 1300, in _send_request
    self.endheaders(body, encode_chunked=encode_chunked)
  File "/usr/lib/python3.6/http/client.py", line 1249, in endheaders
    self._send_output(message_body, encode_chunked=encode_chunked)
  File "/usr/lib/python3.6/http/client.py", line 1036, in _send_output
    self.send(msg)
  File "/usr/lib/python3.6/http/client.py", line 974, in send
    self.connect()
  File "/home/home1/sy189/.local/lib/python3.6/site-packages/urllib3/connection.py", line 184, in connect
    conn = self._new_conn()
  File "/home/home1/sy189/.local/lib/python3.6/site-packages/urllib3/connection.py", line 169, in _new_conn
    self, "Failed to establish a new connection: %s" % e
urllib3.exceptions.NewConnectionError: <urllib3.connection.HTTPConnection object at 0x14ba70e33ac8>: Failed to establish a new connection: [Errno 111] Connection refused

During handling of the above exception, another exception occurred:

Traceback (most recent call last):
  File "/home/home1/sy189/.local/lib/python3.6/site-packages/requests/adapters.py", line 449, in send
    timeout=timeout
  File "/home/home1/sy189/.local/lib/python3.6/site-packages/urllib3/connectionpool.py", line 720, in urlopen
    method, url, error=e, _pool=self, _stacktrace=sys.exc_info()[2]
  File "/home/home1/sy189/.local/lib/python3.6/site-packages/urllib3/util/retry.py", line 436, in increment
    raise MaxRetryError(_pool, url, error or ResponseError(cause))
urllib3.exceptions.MaxRetryError: HTTPConnectionPool(host='localhost', port=8888): Max retries exceeded with url: /events (Caused by NewConnectionError('<urllib3.connection.HTTPConnection object at 0x14ba70e33ac8>: Failed to establish a new connection: [Errno 111] Connection refused',))

During handling of the above exception, another exception occurred:

Traceback (most recent call last):
  File "/home/home1/sy189/.local/lib/python3.6/site-packages/visdom/__init__.py", line 548, in _send
    data=json.dumps(msg),
  File "/home/home1/sy189/.local/lib/python3.6/site-packages/requests/sessions.py", line 581, in post
    return self.request('POST', url, data=data, json=json, **kwargs)
  File "/home/home1/sy189/.local/lib/python3.6/site-packages/requests/sessions.py", line 533, in request
    resp = self.send(prep, **send_kwargs)
  File "/home/home1/sy189/.local/lib/python3.6/site-packages/requests/sessions.py", line 646, in send
    r = adapter.send(request, **kwargs)
  File "/home/home1/sy189/.local/lib/python3.6/site-packages/requests/adapters.py", line 516, in send
    raise ConnectionError(e, request=request)
requests.exceptions.ConnectionError: HTTPConnectionPool(host='localhost', port=8888): Max retries exceeded with url: /events (Caused by NewConnectionError('<urllib3.connection.HTTPConnection object at 0x14ba70e33ac8>: Failed to establish a new connection: [Errno 111] Connection refused',))
Train loss: 0.044:   5%|▍         | 6/133 [00:29<09:58,  4.71s/it]Train loss: 0.044:   5%|▌         | 7/133 [00:29<07:51,  3.74s/it]Traceback (most recent call last):
  File "/home/home1/sy189/.local/lib/python3.6/site-packages/urllib3/connection.py", line 157, in _new_conn
    (self._dns_host, self.port), self.timeout, **extra_kw
  File "/home/home1/sy189/.local/lib/python3.6/site-packages/urllib3/util/connection.py", line 84, in create_connection
    raise err
  File "/home/home1/sy189/.local/lib/python3.6/site-packages/urllib3/util/connection.py", line 74, in create_connection
    sock.connect(sa)
ConnectionRefusedError: [Errno 111] Connection refused

During handling of the above exception, another exception occurred:

Traceback (most recent call last):
  File "/home/home1/sy189/.local/lib/python3.6/site-packages/urllib3/connectionpool.py", line 672, in urlopen
    chunked=chunked,
  File "/home/home1/sy189/.local/lib/python3.6/site-packages/urllib3/connectionpool.py", line 387, in _make_request
    conn.request(method, url, **httplib_request_kw)
  File "/usr/lib/python3.6/http/client.py", line 1254, in request
    self._send_request(method, url, body, headers, encode_chunked)
  File "/usr/lib/python3.6/http/client.py", line 1300, in _send_request
    self.endheaders(body, encode_chunked=encode_chunked)
  File "/usr/lib/python3.6/http/client.py", line 1249, in endheaders
    self._send_output(message_body, encode_chunked=encode_chunked)
  File "/usr/lib/python3.6/http/client.py", line 1036, in _send_output
    self.send(msg)
  File "/usr/lib/python3.6/http/client.py", line 974, in send
    self.connect()
  File "/home/home1/sy189/.local/lib/python3.6/site-packages/urllib3/connection.py", line 184, in connect
    conn = self._new_conn()
  File "/home/home1/sy189/.local/lib/python3.6/site-packages/urllib3/connection.py", line 169, in _new_conn
    self, "Failed to establish a new connection: %s" % e
urllib3.exceptions.NewConnectionError: <urllib3.connection.HTTPConnection object at 0x14ba70e33b70>: Failed to establish a new connection: [Errno 111] Connection refused

During handling of the above exception, another exception occurred:

Traceback (most recent call last):
  File "/home/home1/sy189/.local/lib/python3.6/site-packages/requests/adapters.py", line 449, in send
    timeout=timeout
  File "/home/home1/sy189/.local/lib/python3.6/site-packages/urllib3/connectionpool.py", line 720, in urlopen
    method, url, error=e, _pool=self, _stacktrace=sys.exc_info()[2]
  File "/home/home1/sy189/.local/lib/python3.6/site-packages/urllib3/util/retry.py", line 436, in increment
    raise MaxRetryError(_pool, url, error or ResponseError(cause))
urllib3.exceptions.MaxRetryError: HTTPConnectionPool(host='localhost', port=8888): Max retries exceeded with url: /events (Caused by NewConnectionError('<urllib3.connection.HTTPConnection object at 0x14ba70e33b70>: Failed to establish a new connection: [Errno 111] Connection refused',))

During handling of the above exception, another exception occurred:

Traceback (most recent call last):
  File "/home/home1/sy189/.local/lib/python3.6/site-packages/visdom/__init__.py", line 548, in _send
    data=json.dumps(msg),
  File "/home/home1/sy189/.local/lib/python3.6/site-packages/requests/sessions.py", line 581, in post
    return self.request('POST', url, data=data, json=json, **kwargs)
  File "/home/home1/sy189/.local/lib/python3.6/site-packages/requests/sessions.py", line 533, in request
    resp = self.send(prep, **send_kwargs)
  File "/home/home1/sy189/.local/lib/python3.6/site-packages/requests/sessions.py", line 646, in send
    r = adapter.send(request, **kwargs)
  File "/home/home1/sy189/.local/lib/python3.6/site-packages/requests/adapters.py", line 516, in send
    raise ConnectionError(e, request=request)
requests.exceptions.ConnectionError: HTTPConnectionPool(host='localhost', port=8888): Max retries exceeded with url: /events (Caused by NewConnectionError('<urllib3.connection.HTTPConnection object at 0x14ba70e33b70>: Failed to establish a new connection: [Errno 111] Connection refused',))
Train loss: 0.044:   5%|▌         | 7/133 [00:31<07:51,  3.74s/it]Train loss: 0.044:   6%|▌         | 8/133 [00:31<06:25,  3.08s/it]Traceback (most recent call last):
  File "/home/home1/sy189/.local/lib/python3.6/site-packages/urllib3/connection.py", line 157, in _new_conn
    (self._dns_host, self.port), self.timeout, **extra_kw
  File "/home/home1/sy189/.local/lib/python3.6/site-packages/urllib3/util/connection.py", line 84, in create_connection
    raise err
  File "/home/home1/sy189/.local/lib/python3.6/site-packages/urllib3/util/connection.py", line 74, in create_connection
    sock.connect(sa)
ConnectionRefusedError: [Errno 111] Connection refused

During handling of the above exception, another exception occurred:

Traceback (most recent call last):
  File "/home/home1/sy189/.local/lib/python3.6/site-packages/urllib3/connectionpool.py", line 672, in urlopen
    chunked=chunked,
  File "/home/home1/sy189/.local/lib/python3.6/site-packages/urllib3/connectionpool.py", line 387, in _make_request
    conn.request(method, url, **httplib_request_kw)
  File "/usr/lib/python3.6/http/client.py", line 1254, in request
    self._send_request(method, url, body, headers, encode_chunked)
  File "/usr/lib/python3.6/http/client.py", line 1300, in _send_request
    self.endheaders(body, encode_chunked=encode_chunked)
  File "/usr/lib/python3.6/http/client.py", line 1249, in endheaders
    self._send_output(message_body, encode_chunked=encode_chunked)
  File "/usr/lib/python3.6/http/client.py", line 1036, in _send_output
    self.send(msg)
  File "/usr/lib/python3.6/http/client.py", line 974, in send
    self.connect()
  File "/home/home1/sy189/.local/lib/python3.6/site-packages/urllib3/connection.py", line 184, in connect
    conn = self._new_conn()
  File "/home/home1/sy189/.local/lib/python3.6/site-packages/urllib3/connection.py", line 169, in _new_conn
    self, "Failed to establish a new connection: %s" % e
urllib3.exceptions.NewConnectionError: <urllib3.connection.HTTPConnection object at 0x14ba70e33c50>: Failed to establish a new connection: [Errno 111] Connection refused

During handling of the above exception, another exception occurred:

Traceback (most recent call last):
  File "/home/home1/sy189/.local/lib/python3.6/site-packages/requests/adapters.py", line 449, in send
    timeout=timeout
  File "/home/home1/sy189/.local/lib/python3.6/site-packages/urllib3/connectionpool.py", line 720, in urlopen
    method, url, error=e, _pool=self, _stacktrace=sys.exc_info()[2]
  File "/home/home1/sy189/.local/lib/python3.6/site-packages/urllib3/util/retry.py", line 436, in increment
    raise MaxRetryError(_pool, url, error or ResponseError(cause))
urllib3.exceptions.MaxRetryError: HTTPConnectionPool(host='localhost', port=8888): Max retries exceeded with url: /events (Caused by NewConnectionError('<urllib3.connection.HTTPConnection object at 0x14ba70e33c50>: Failed to establish a new connection: [Errno 111] Connection refused',))

During handling of the above exception, another exception occurred:

Traceback (most recent call last):
  File "/home/home1/sy189/.local/lib/python3.6/site-packages/visdom/__init__.py", line 548, in _send
    data=json.dumps(msg),
  File "/home/home1/sy189/.local/lib/python3.6/site-packages/requests/sessions.py", line 581, in post
    return self.request('POST', url, data=data, json=json, **kwargs)
  File "/home/home1/sy189/.local/lib/python3.6/site-packages/requests/sessions.py", line 533, in request
    resp = self.send(prep, **send_kwargs)
  File "/home/home1/sy189/.local/lib/python3.6/site-packages/requests/sessions.py", line 646, in send
    r = adapter.send(request, **kwargs)
  File "/home/home1/sy189/.local/lib/python3.6/site-packages/requests/adapters.py", line 516, in send
    raise ConnectionError(e, request=request)
requests.exceptions.ConnectionError: HTTPConnectionPool(host='localhost', port=8888): Max retries exceeded with url: /events (Caused by NewConnectionError('<urllib3.connection.HTTPConnection object at 0x14ba70e33c50>: Failed to establish a new connection: [Errno 111] Connection refused',))
Train loss: 0.044:   6%|▌         | 8/133 [00:32<06:25,  3.08s/it]Train loss: 0.044:   7%|▋         | 9/133 [00:32<05:16,  2.55s/it]Traceback (most recent call last):
  File "/home/home1/sy189/.local/lib/python3.6/site-packages/urllib3/connection.py", line 157, in _new_conn
    (self._dns_host, self.port), self.timeout, **extra_kw
  File "/home/home1/sy189/.local/lib/python3.6/site-packages/urllib3/util/connection.py", line 84, in create_connection
    raise err
  File "/home/home1/sy189/.local/lib/python3.6/site-packages/urllib3/util/connection.py", line 74, in create_connection
    sock.connect(sa)
ConnectionRefusedError: [Errno 111] Connection refused

During handling of the above exception, another exception occurred:

Traceback (most recent call last):
  File "/home/home1/sy189/.local/lib/python3.6/site-packages/urllib3/connectionpool.py", line 672, in urlopen
    chunked=chunked,
  File "/home/home1/sy189/.local/lib/python3.6/site-packages/urllib3/connectionpool.py", line 387, in _make_request
    conn.request(method, url, **httplib_request_kw)
  File "/usr/lib/python3.6/http/client.py", line 1254, in request
    self._send_request(method, url, body, headers, encode_chunked)
  File "/usr/lib/python3.6/http/client.py", line 1300, in _send_request
    self.endheaders(body, encode_chunked=encode_chunked)
  File "/usr/lib/python3.6/http/client.py", line 1249, in endheaders
    self._send_output(message_body, encode_chunked=encode_chunked)
  File "/usr/lib/python3.6/http/client.py", line 1036, in _send_output
    self.send(msg)
  File "/usr/lib/python3.6/http/client.py", line 974, in send
    self.connect()
  File "/home/home1/sy189/.local/lib/python3.6/site-packages/urllib3/connection.py", line 184, in connect
    conn = self._new_conn()
  File "/home/home1/sy189/.local/lib/python3.6/site-packages/urllib3/connection.py", line 169, in _new_conn
    self, "Failed to establish a new connection: %s" % e
urllib3.exceptions.NewConnectionError: <urllib3.connection.HTTPConnection object at 0x14ba70ea6978>: Failed to establish a new connection: [Errno 111] Connection refused

During handling of the above exception, another exception occurred:

Traceback (most recent call last):
  File "/home/home1/sy189/.local/lib/python3.6/site-packages/requests/adapters.py", line 449, in send
    timeout=timeout
  File "/home/home1/sy189/.local/lib/python3.6/site-packages/urllib3/connectionpool.py", line 720, in urlopen
    method, url, error=e, _pool=self, _stacktrace=sys.exc_info()[2]
  File "/home/home1/sy189/.local/lib/python3.6/site-packages/urllib3/util/retry.py", line 436, in increment
    raise MaxRetryError(_pool, url, error or ResponseError(cause))
urllib3.exceptions.MaxRetryError: HTTPConnectionPool(host='localhost', port=8888): Max retries exceeded with url: /events (Caused by NewConnectionError('<urllib3.connection.HTTPConnection object at 0x14ba70ea6978>: Failed to establish a new connection: [Errno 111] Connection refused',))

During handling of the above exception, another exception occurred:

Traceback (most recent call last):
  File "/home/home1/sy189/.local/lib/python3.6/site-packages/visdom/__init__.py", line 548, in _send
    data=json.dumps(msg),
  File "/home/home1/sy189/.local/lib/python3.6/site-packages/requests/sessions.py", line 581, in post
    return self.request('POST', url, data=data, json=json, **kwargs)
  File "/home/home1/sy189/.local/lib/python3.6/site-packages/requests/sessions.py", line 533, in request
    resp = self.send(prep, **send_kwargs)
  File "/home/home1/sy189/.local/lib/python3.6/site-packages/requests/sessions.py", line 646, in send
    r = adapter.send(request, **kwargs)
  File "/home/home1/sy189/.local/lib/python3.6/site-packages/requests/adapters.py", line 516, in send
    raise ConnectionError(e, request=request)
requests.exceptions.ConnectionError: HTTPConnectionPool(host='localhost', port=8888): Max retries exceeded with url: /events (Caused by NewConnectionError('<urllib3.connection.HTTPConnection object at 0x14ba70ea6978>: Failed to establish a new connection: [Errno 111] Connection refused',))
Train loss: 0.044:   7%|▋         | 9/133 [00:33<05:16,  2.55s/it]Train loss: 0.044:   8%|▊         | 10/133 [00:33<04:27,  2.17s/it]Traceback (most recent call last):
  File "/home/home1/sy189/.local/lib/python3.6/site-packages/urllib3/connection.py", line 157, in _new_conn
    (self._dns_host, self.port), self.timeout, **extra_kw
  File "/home/home1/sy189/.local/lib/python3.6/site-packages/urllib3/util/connection.py", line 84, in create_connection
    raise err
  File "/home/home1/sy189/.local/lib/python3.6/site-packages/urllib3/util/connection.py", line 74, in create_connection
    sock.connect(sa)
ConnectionRefusedError: [Errno 111] Connection refused

During handling of the above exception, another exception occurred:

Traceback (most recent call last):
  File "/home/home1/sy189/.local/lib/python3.6/site-packages/urllib3/connectionpool.py", line 672, in urlopen
    chunked=chunked,
  File "/home/home1/sy189/.local/lib/python3.6/site-packages/urllib3/connectionpool.py", line 387, in _make_request
    conn.request(method, url, **httplib_request_kw)
  File "/usr/lib/python3.6/http/client.py", line 1254, in request
    self._send_request(method, url, body, headers, encode_chunked)
  File "/usr/lib/python3.6/http/client.py", line 1300, in _send_request
    self.endheaders(body, encode_chunked=encode_chunked)
  File "/usr/lib/python3.6/http/client.py", line 1249, in endheaders
    self._send_output(message_body, encode_chunked=encode_chunked)
  File "/usr/lib/python3.6/http/client.py", line 1036, in _send_output
    self.send(msg)
  File "/usr/lib/python3.6/http/client.py", line 974, in send
    self.connect()
  File "/home/home1/sy189/.local/lib/python3.6/site-packages/urllib3/connection.py", line 184, in connect
    conn = self._new_conn()
  File "/home/home1/sy189/.local/lib/python3.6/site-packages/urllib3/connection.py", line 169, in _new_conn
    self, "Failed to establish a new connection: %s" % e
urllib3.exceptions.NewConnectionError: <urllib3.connection.HTTPConnection object at 0x14ba70ea6198>: Failed to establish a new connection: [Errno 111] Connection refused

During handling of the above exception, another exception occurred:

Traceback (most recent call last):
  File "/home/home1/sy189/.local/lib/python3.6/site-packages/requests/adapters.py", line 449, in send
    timeout=timeout
  File "/home/home1/sy189/.local/lib/python3.6/site-packages/urllib3/connectionpool.py", line 720, in urlopen
    method, url, error=e, _pool=self, _stacktrace=sys.exc_info()[2]
  File "/home/home1/sy189/.local/lib/python3.6/site-packages/urllib3/util/retry.py", line 436, in increment
    raise MaxRetryError(_pool, url, error or ResponseError(cause))
urllib3.exceptions.MaxRetryError: HTTPConnectionPool(host='localhost', port=8888): Max retries exceeded with url: /events (Caused by NewConnectionError('<urllib3.connection.HTTPConnection object at 0x14ba70ea6198>: Failed to establish a new connection: [Errno 111] Connection refused',))

During handling of the above exception, another exception occurred:

Traceback (most recent call last):
  File "/home/home1/sy189/.local/lib/python3.6/site-packages/visdom/__init__.py", line 548, in _send
    data=json.dumps(msg),
  File "/home/home1/sy189/.local/lib/python3.6/site-packages/requests/sessions.py", line 581, in post
    return self.request('POST', url, data=data, json=json, **kwargs)
  File "/home/home1/sy189/.local/lib/python3.6/site-packages/requests/sessions.py", line 533, in request
    resp = self.send(prep, **send_kwargs)
  File "/home/home1/sy189/.local/lib/python3.6/site-packages/requests/sessions.py", line 646, in send
    r = adapter.send(request, **kwargs)
  File "/home/home1/sy189/.local/lib/python3.6/site-packages/requests/adapters.py", line 516, in send
    raise ConnectionError(e, request=request)
requests.exceptions.ConnectionError: HTTPConnectionPool(host='localhost', port=8888): Max retries exceeded with url: /events (Caused by NewConnectionError('<urllib3.connection.HTTPConnection object at 0x14ba70ea6198>: Failed to establish a new connection: [Errno 111] Connection refused',))
Train loss: 0.044:   8%|▊         | 10/133 [00:35<04:27,  2.17s/it]Train loss: 0.044:   8%|▊         | 11/133 [00:35<03:52,  1.91s/it]Traceback (most recent call last):
  File "/home/home1/sy189/.local/lib/python3.6/site-packages/urllib3/connection.py", line 157, in _new_conn
    (self._dns_host, self.port), self.timeout, **extra_kw
  File "/home/home1/sy189/.local/lib/python3.6/site-packages/urllib3/util/connection.py", line 84, in create_connection
    raise err
  File "/home/home1/sy189/.local/lib/python3.6/site-packages/urllib3/util/connection.py", line 74, in create_connection
    sock.connect(sa)
ConnectionRefusedError: [Errno 111] Connection refused

During handling of the above exception, another exception occurred:

Traceback (most recent call last):
  File "/home/home1/sy189/.local/lib/python3.6/site-packages/urllib3/connectionpool.py", line 672, in urlopen
    chunked=chunked,
  File "/home/home1/sy189/.local/lib/python3.6/site-packages/urllib3/connectionpool.py", line 387, in _make_request
    conn.request(method, url, **httplib_request_kw)
  File "/usr/lib/python3.6/http/client.py", line 1254, in request
    self._send_request(method, url, body, headers, encode_chunked)
  File "/usr/lib/python3.6/http/client.py", line 1300, in _send_request
    self.endheaders(body, encode_chunked=encode_chunked)
  File "/usr/lib/python3.6/http/client.py", line 1249, in endheaders
    self._send_output(message_body, encode_chunked=encode_chunked)
  File "/usr/lib/python3.6/http/client.py", line 1036, in _send_output
    self.send(msg)
  File "/usr/lib/python3.6/http/client.py", line 974, in send
    self.connect()
  File "/home/home1/sy189/.local/lib/python3.6/site-packages/urllib3/connection.py", line 184, in connect
    conn = self._new_conn()
  File "/home/home1/sy189/.local/lib/python3.6/site-packages/urllib3/connection.py", line 169, in _new_conn
    self, "Failed to establish a new connection: %s" % e
urllib3.exceptions.NewConnectionError: <urllib3.connection.HTTPConnection object at 0x14ba70ea6978>: Failed to establish a new connection: [Errno 111] Connection refused

During handling of the above exception, another exception occurred:

Traceback (most recent call last):
  File "/home/home1/sy189/.local/lib/python3.6/site-packages/requests/adapters.py", line 449, in send
    timeout=timeout
  File "/home/home1/sy189/.local/lib/python3.6/site-packages/urllib3/connectionpool.py", line 720, in urlopen
    method, url, error=e, _pool=self, _stacktrace=sys.exc_info()[2]
  File "/home/home1/sy189/.local/lib/python3.6/site-packages/urllib3/util/retry.py", line 436, in increment
    raise MaxRetryError(_pool, url, error or ResponseError(cause))
urllib3.exceptions.MaxRetryError: HTTPConnectionPool(host='localhost', port=8888): Max retries exceeded with url: /events (Caused by NewConnectionError('<urllib3.connection.HTTPConnection object at 0x14ba70ea6978>: Failed to establish a new connection: [Errno 111] Connection refused',))

During handling of the above exception, another exception occurred:

Traceback (most recent call last):
  File "/home/home1/sy189/.local/lib/python3.6/site-packages/visdom/__init__.py", line 548, in _send
    data=json.dumps(msg),
  File "/home/home1/sy189/.local/lib/python3.6/site-packages/requests/sessions.py", line 581, in post
    return self.request('POST', url, data=data, json=json, **kwargs)
  File "/home/home1/sy189/.local/lib/python3.6/site-packages/requests/sessions.py", line 533, in request
    resp = self.send(prep, **send_kwargs)
  File "/home/home1/sy189/.local/lib/python3.6/site-packages/requests/sessions.py", line 646, in send
    r = adapter.send(request, **kwargs)
  File "/home/home1/sy189/.local/lib/python3.6/site-packages/requests/adapters.py", line 516, in send
    raise ConnectionError(e, request=request)
requests.exceptions.ConnectionError: HTTPConnectionPool(host='localhost', port=8888): Max retries exceeded with url: /events (Caused by NewConnectionError('<urllib3.connection.HTTPConnection object at 0x14ba70ea6978>: Failed to establish a new connection: [Errno 111] Connection refused',))
Train loss: 0.044:   8%|▊         | 11/133 [00:36<03:52,  1.91s/it]Train loss: 0.044:   9%|▉         | 12/133 [00:36<03:31,  1.75s/it]Traceback (most recent call last):
  File "/home/home1/sy189/.local/lib/python3.6/site-packages/urllib3/connection.py", line 157, in _new_conn
    (self._dns_host, self.port), self.timeout, **extra_kw
  File "/home/home1/sy189/.local/lib/python3.6/site-packages/urllib3/util/connection.py", line 84, in create_connection
    raise err
  File "/home/home1/sy189/.local/lib/python3.6/site-packages/urllib3/util/connection.py", line 74, in create_connection
    sock.connect(sa)
ConnectionRefusedError: [Errno 111] Connection refused

During handling of the above exception, another exception occurred:

Traceback (most recent call last):
  File "/home/home1/sy189/.local/lib/python3.6/site-packages/urllib3/connectionpool.py", line 672, in urlopen
    chunked=chunked,
  File "/home/home1/sy189/.local/lib/python3.6/site-packages/urllib3/connectionpool.py", line 387, in _make_request
    conn.request(method, url, **httplib_request_kw)
  File "/usr/lib/python3.6/http/client.py", line 1254, in request
    self._send_request(method, url, body, headers, encode_chunked)
  File "/usr/lib/python3.6/http/client.py", line 1300, in _send_request
    self.endheaders(body, encode_chunked=encode_chunked)
  File "/usr/lib/python3.6/http/client.py", line 1249, in endheaders
    self._send_output(message_body, encode_chunked=encode_chunked)
  File "/usr/lib/python3.6/http/client.py", line 1036, in _send_output
    self.send(msg)
  File "/usr/lib/python3.6/http/client.py", line 974, in send
    self.connect()
  File "/home/home1/sy189/.local/lib/python3.6/site-packages/urllib3/connection.py", line 184, in connect
    conn = self._new_conn()
  File "/home/home1/sy189/.local/lib/python3.6/site-packages/urllib3/connection.py", line 169, in _new_conn
    self, "Failed to establish a new connection: %s" % e
urllib3.exceptions.NewConnectionError: <urllib3.connection.HTTPConnection object at 0x14ba70ea63c8>: Failed to establish a new connection: [Errno 111] Connection refused

During handling of the above exception, another exception occurred:

Traceback (most recent call last):
  File "/home/home1/sy189/.local/lib/python3.6/site-packages/requests/adapters.py", line 449, in send
    timeout=timeout
  File "/home/home1/sy189/.local/lib/python3.6/site-packages/urllib3/connectionpool.py", line 720, in urlopen
    method, url, error=e, _pool=self, _stacktrace=sys.exc_info()[2]
  File "/home/home1/sy189/.local/lib/python3.6/site-packages/urllib3/util/retry.py", line 436, in increment
    raise MaxRetryError(_pool, url, error or ResponseError(cause))
urllib3.exceptions.MaxRetryError: HTTPConnectionPool(host='localhost', port=8888): Max retries exceeded with url: /events (Caused by NewConnectionError('<urllib3.connection.HTTPConnection object at 0x14ba70ea63c8>: Failed to establish a new connection: [Errno 111] Connection refused',))

During handling of the above exception, another exception occurred:

Traceback (most recent call last):
  File "/home/home1/sy189/.local/lib/python3.6/site-packages/visdom/__init__.py", line 548, in _send
    data=json.dumps(msg),
  File "/home/home1/sy189/.local/lib/python3.6/site-packages/requests/sessions.py", line 581, in post
    return self.request('POST', url, data=data, json=json, **kwargs)
  File "/home/home1/sy189/.local/lib/python3.6/site-packages/requests/sessions.py", line 533, in request
    resp = self.send(prep, **send_kwargs)
  File "/home/home1/sy189/.local/lib/python3.6/site-packages/requests/sessions.py", line 646, in send
    r = adapter.send(request, **kwargs)
  File "/home/home1/sy189/.local/lib/python3.6/site-packages/requests/adapters.py", line 516, in send
    raise ConnectionError(e, request=request)
requests.exceptions.ConnectionError: HTTPConnectionPool(host='localhost', port=8888): Max retries exceeded with url: /events (Caused by NewConnectionError('<urllib3.connection.HTTPConnection object at 0x14ba70ea63c8>: Failed to establish a new connection: [Errno 111] Connection refused',))
Train loss: 0.044:   9%|▉         | 12/133 [00:37<03:31,  1.75s/it]Train loss: 0.044:  10%|▉         | 13/133 [00:37<03:13,  1.62s/it]Traceback (most recent call last):
  File "/home/home1/sy189/.local/lib/python3.6/site-packages/urllib3/connection.py", line 157, in _new_conn
    (self._dns_host, self.port), self.timeout, **extra_kw
  File "/home/home1/sy189/.local/lib/python3.6/site-packages/urllib3/util/connection.py", line 84, in create_connection
    raise err
  File "/home/home1/sy189/.local/lib/python3.6/site-packages/urllib3/util/connection.py", line 74, in create_connection
    sock.connect(sa)
ConnectionRefusedError: [Errno 111] Connection refused

During handling of the above exception, another exception occurred:

Traceback (most recent call last):
  File "/home/home1/sy189/.local/lib/python3.6/site-packages/urllib3/connectionpool.py", line 672, in urlopen
    chunked=chunked,
  File "/home/home1/sy189/.local/lib/python3.6/site-packages/urllib3/connectionpool.py", line 387, in _make_request
    conn.request(method, url, **httplib_request_kw)
  File "/usr/lib/python3.6/http/client.py", line 1254, in request
    self._send_request(method, url, body, headers, encode_chunked)
  File "/usr/lib/python3.6/http/client.py", line 1300, in _send_request
    self.endheaders(body, encode_chunked=encode_chunked)
  File "/usr/lib/python3.6/http/client.py", line 1249, in endheaders
    self._send_output(message_body, encode_chunked=encode_chunked)
  File "/usr/lib/python3.6/http/client.py", line 1036, in _send_output
    self.send(msg)
  File "/usr/lib/python3.6/http/client.py", line 974, in send
    self.connect()
  File "/home/home1/sy189/.local/lib/python3.6/site-packages/urllib3/connection.py", line 184, in connect
    conn = self._new_conn()
  File "/home/home1/sy189/.local/lib/python3.6/site-packages/urllib3/connection.py", line 169, in _new_conn
    self, "Failed to establish a new connection: %s" % e
urllib3.exceptions.NewConnectionError: <urllib3.connection.HTTPConnection object at 0x14ba70ea6828>: Failed to establish a new connection: [Errno 111] Connection refused

During handling of the above exception, another exception occurred:

Traceback (most recent call last):
  File "/home/home1/sy189/.local/lib/python3.6/site-packages/requests/adapters.py", line 449, in send
    timeout=timeout
  File "/home/home1/sy189/.local/lib/python3.6/site-packages/urllib3/connectionpool.py", line 720, in urlopen
    method, url, error=e, _pool=self, _stacktrace=sys.exc_info()[2]
  File "/home/home1/sy189/.local/lib/python3.6/site-packages/urllib3/util/retry.py", line 436, in increment
    raise MaxRetryError(_pool, url, error or ResponseError(cause))
urllib3.exceptions.MaxRetryError: HTTPConnectionPool(host='localhost', port=8888): Max retries exceeded with url: /events (Caused by NewConnectionError('<urllib3.connection.HTTPConnection object at 0x14ba70ea6828>: Failed to establish a new connection: [Errno 111] Connection refused',))

During handling of the above exception, another exception occurred:

Traceback (most recent call last):
  File "/home/home1/sy189/.local/lib/python3.6/site-packages/visdom/__init__.py", line 548, in _send
    data=json.dumps(msg),
  File "/home/home1/sy189/.local/lib/python3.6/site-packages/requests/sessions.py", line 581, in post
    return self.request('POST', url, data=data, json=json, **kwargs)
  File "/home/home1/sy189/.local/lib/python3.6/site-packages/requests/sessions.py", line 533, in request
    resp = self.send(prep, **send_kwargs)
  File "/home/home1/sy189/.local/lib/python3.6/site-packages/requests/sessions.py", line 646, in send
    r = adapter.send(request, **kwargs)
  File "/home/home1/sy189/.local/lib/python3.6/site-packages/requests/adapters.py", line 516, in send
    raise ConnectionError(e, request=request)
requests.exceptions.ConnectionError: HTTPConnectionPool(host='localhost', port=8888): Max retries exceeded with url: /events (Caused by NewConnectionError('<urllib3.connection.HTTPConnection object at 0x14ba70ea6828>: Failed to establish a new connection: [Errno 111] Connection refused',))
Train loss: 0.044:  10%|▉         | 13/133 [00:39<03:13,  1.62s/it]Train loss: 0.044:  11%|█         | 14/133 [00:39<03:03,  1.54s/it]Traceback (most recent call last):
  File "/home/home1/sy189/.local/lib/python3.6/site-packages/urllib3/connection.py", line 157, in _new_conn
    (self._dns_host, self.port), self.timeout, **extra_kw
  File "/home/home1/sy189/.local/lib/python3.6/site-packages/urllib3/util/connection.py", line 84, in create_connection
    raise err
  File "/home/home1/sy189/.local/lib/python3.6/site-packages/urllib3/util/connection.py", line 74, in create_connection
    sock.connect(sa)
ConnectionRefusedError: [Errno 111] Connection refused

During handling of the above exception, another exception occurred:

Traceback (most recent call last):
  File "/home/home1/sy189/.local/lib/python3.6/site-packages/urllib3/connectionpool.py", line 672, in urlopen
    chunked=chunked,
  File "/home/home1/sy189/.local/lib/python3.6/site-packages/urllib3/connectionpool.py", line 387, in _make_request
    conn.request(method, url, **httplib_request_kw)
  File "/usr/lib/python3.6/http/client.py", line 1254, in request
    self._send_request(method, url, body, headers, encode_chunked)
  File "/usr/lib/python3.6/http/client.py", line 1300, in _send_request
    self.endheaders(body, encode_chunked=encode_chunked)
  File "/usr/lib/python3.6/http/client.py", line 1249, in endheaders
    self._send_output(message_body, encode_chunked=encode_chunked)
  File "/usr/lib/python3.6/http/client.py", line 1036, in _send_output
    self.send(msg)
  File "/usr/lib/python3.6/http/client.py", line 974, in send
    self.connect()
  File "/home/home1/sy189/.local/lib/python3.6/site-packages/urllib3/connection.py", line 184, in connect
    conn = self._new_conn()
  File "/home/home1/sy189/.local/lib/python3.6/site-packages/urllib3/connection.py", line 169, in _new_conn
    self, "Failed to establish a new connection: %s" % e
urllib3.exceptions.NewConnectionError: <urllib3.connection.HTTPConnection object at 0x14ba7076ac18>: Failed to establish a new connection: [Errno 111] Connection refused

During handling of the above exception, another exception occurred:

Traceback (most recent call last):
  File "/home/home1/sy189/.local/lib/python3.6/site-packages/requests/adapters.py", line 449, in send
    timeout=timeout
  File "/home/home1/sy189/.local/lib/python3.6/site-packages/urllib3/connectionpool.py", line 720, in urlopen
    method, url, error=e, _pool=self, _stacktrace=sys.exc_info()[2]
  File "/home/home1/sy189/.local/lib/python3.6/site-packages/urllib3/util/retry.py", line 436, in increment
    raise MaxRetryError(_pool, url, error or ResponseError(cause))
urllib3.exceptions.MaxRetryError: HTTPConnectionPool(host='localhost', port=8888): Max retries exceeded with url: /events (Caused by NewConnectionError('<urllib3.connection.HTTPConnection object at 0x14ba7076ac18>: Failed to establish a new connection: [Errno 111] Connection refused',))

During handling of the above exception, another exception occurred:

Traceback (most recent call last):
  File "/home/home1/sy189/.local/lib/python3.6/site-packages/visdom/__init__.py", line 548, in _send
    data=json.dumps(msg),
  File "/home/home1/sy189/.local/lib/python3.6/site-packages/requests/sessions.py", line 581, in post
    return self.request('POST', url, data=data, json=json, **kwargs)
  File "/home/home1/sy189/.local/lib/python3.6/site-packages/requests/sessions.py", line 533, in request
    resp = self.send(prep, **send_kwargs)
  File "/home/home1/sy189/.local/lib/python3.6/site-packages/requests/sessions.py", line 646, in send
    r = adapter.send(request, **kwargs)
  File "/home/home1/sy189/.local/lib/python3.6/site-packages/requests/adapters.py", line 516, in send
    raise ConnectionError(e, request=request)
requests.exceptions.ConnectionError: HTTPConnectionPool(host='localhost', port=8888): Max retries exceeded with url: /events (Caused by NewConnectionError('<urllib3.connection.HTTPConnection object at 0x14ba7076ac18>: Failed to establish a new connection: [Errno 111] Connection refused',))
Train loss: 0.044:  11%|█         | 14/133 [00:40<03:03,  1.54s/it]Train loss: 0.044:  11%|█▏        | 15/133 [00:40<02:53,  1.47s/it]Traceback (most recent call last):
  File "/home/home1/sy189/.local/lib/python3.6/site-packages/urllib3/connection.py", line 157, in _new_conn
    (self._dns_host, self.port), self.timeout, **extra_kw
  File "/home/home1/sy189/.local/lib/python3.6/site-packages/urllib3/util/connection.py", line 84, in create_connection
    raise err
  File "/home/home1/sy189/.local/lib/python3.6/site-packages/urllib3/util/connection.py", line 74, in create_connection
    sock.connect(sa)
ConnectionRefusedError: [Errno 111] Connection refused

During handling of the above exception, another exception occurred:

Traceback (most recent call last):
  File "/home/home1/sy189/.local/lib/python3.6/site-packages/urllib3/connectionpool.py", line 672, in urlopen
    chunked=chunked,
  File "/home/home1/sy189/.local/lib/python3.6/site-packages/urllib3/connectionpool.py", line 387, in _make_request
    conn.request(method, url, **httplib_request_kw)
  File "/usr/lib/python3.6/http/client.py", line 1254, in request
    self._send_request(method, url, body, headers, encode_chunked)
  File "/usr/lib/python3.6/http/client.py", line 1300, in _send_request
    self.endheaders(body, encode_chunked=encode_chunked)
  File "/usr/lib/python3.6/http/client.py", line 1249, in endheaders
    self._send_output(message_body, encode_chunked=encode_chunked)
  File "/usr/lib/python3.6/http/client.py", line 1036, in _send_output
    self.send(msg)
  File "/usr/lib/python3.6/http/client.py", line 974, in send
    self.connect()
  File "/home/home1/sy189/.local/lib/python3.6/site-packages/urllib3/connection.py", line 184, in connect
    conn = self._new_conn()
  File "/home/home1/sy189/.local/lib/python3.6/site-packages/urllib3/connection.py", line 169, in _new_conn
    self, "Failed to establish a new connection: %s" % e
urllib3.exceptions.NewConnectionError: <urllib3.connection.HTTPConnection object at 0x14ba70ea6ba8>: Failed to establish a new connection: [Errno 111] Connection refused

During handling of the above exception, another exception occurred:

Traceback (most recent call last):
  File "/home/home1/sy189/.local/lib/python3.6/site-packages/requests/adapters.py", line 449, in send
    timeout=timeout
  File "/home/home1/sy189/.local/lib/python3.6/site-packages/urllib3/connectionpool.py", line 720, in urlopen
    method, url, error=e, _pool=self, _stacktrace=sys.exc_info()[2]
  File "/home/home1/sy189/.local/lib/python3.6/site-packages/urllib3/util/retry.py", line 436, in increment
    raise MaxRetryError(_pool, url, error or ResponseError(cause))
urllib3.exceptions.MaxRetryError: HTTPConnectionPool(host='localhost', port=8888): Max retries exceeded with url: /events (Caused by NewConnectionError('<urllib3.connection.HTTPConnection object at 0x14ba70ea6ba8>: Failed to establish a new connection: [Errno 111] Connection refused',))

During handling of the above exception, another exception occurred:

Traceback (most recent call last):
  File "/home/home1/sy189/.local/lib/python3.6/site-packages/visdom/__init__.py", line 548, in _send
    data=json.dumps(msg),
  File "/home/home1/sy189/.local/lib/python3.6/site-packages/requests/sessions.py", line 581, in post
    return self.request('POST', url, data=data, json=json, **kwargs)
  File "/home/home1/sy189/.local/lib/python3.6/site-packages/requests/sessions.py", line 533, in request
    resp = self.send(prep, **send_kwargs)
  File "/home/home1/sy189/.local/lib/python3.6/site-packages/requests/sessions.py", line 646, in send
    r = adapter.send(request, **kwargs)
  File "/home/home1/sy189/.local/lib/python3.6/site-packages/requests/adapters.py", line 516, in send
    raise ConnectionError(e, request=request)
requests.exceptions.ConnectionError: HTTPConnectionPool(host='localhost', port=8888): Max retries exceeded with url: /events (Caused by NewConnectionError('<urllib3.connection.HTTPConnection object at 0x14ba70ea6ba8>: Failed to establish a new connection: [Errno 111] Connection refused',))
Train loss: 0.044:  11%|█▏        | 15/133 [00:41<02:53,  1.47s/it]Train loss: 0.044:  12%|█▏        | 16/133 [00:41<02:44,  1.41s/it]Traceback (most recent call last):
  File "/home/home1/sy189/.local/lib/python3.6/site-packages/urllib3/connection.py", line 157, in _new_conn
    (self._dns_host, self.port), self.timeout, **extra_kw
  File "/home/home1/sy189/.local/lib/python3.6/site-packages/urllib3/util/connection.py", line 84, in create_connection
    raise err
  File "/home/home1/sy189/.local/lib/python3.6/site-packages/urllib3/util/connection.py", line 74, in create_connection
    sock.connect(sa)
ConnectionRefusedError: [Errno 111] Connection refused

During handling of the above exception, another exception occurred:

Traceback (most recent call last):
  File "/home/home1/sy189/.local/lib/python3.6/site-packages/urllib3/connectionpool.py", line 672, in urlopen
    chunked=chunked,
  File "/home/home1/sy189/.local/lib/python3.6/site-packages/urllib3/connectionpool.py", line 387, in _make_request
    conn.request(method, url, **httplib_request_kw)
  File "/usr/lib/python3.6/http/client.py", line 1254, in request
    self._send_request(method, url, body, headers, encode_chunked)
  File "/usr/lib/python3.6/http/client.py", line 1300, in _send_request
    self.endheaders(body, encode_chunked=encode_chunked)
  File "/usr/lib/python3.6/http/client.py", line 1249, in endheaders
    self._send_output(message_body, encode_chunked=encode_chunked)
  File "/usr/lib/python3.6/http/client.py", line 1036, in _send_output
    self.send(msg)
  File "/usr/lib/python3.6/http/client.py", line 974, in send
    self.connect()
  File "/home/home1/sy189/.local/lib/python3.6/site-packages/urllib3/connection.py", line 184, in connect
    conn = self._new_conn()
  File "/home/home1/sy189/.local/lib/python3.6/site-packages/urllib3/connection.py", line 169, in _new_conn
    self, "Failed to establish a new connection: %s" % e
urllib3.exceptions.NewConnectionError: <urllib3.connection.HTTPConnection object at 0x14ba70ea6ba8>: Failed to establish a new connection: [Errno 111] Connection refused

During handling of the above exception, another exception occurred:

Traceback (most recent call last):
  File "/home/home1/sy189/.local/lib/python3.6/site-packages/requests/adapters.py", line 449, in send
    timeout=timeout
  File "/home/home1/sy189/.local/lib/python3.6/site-packages/urllib3/connectionpool.py", line 720, in urlopen
    method, url, error=e, _pool=self, _stacktrace=sys.exc_info()[2]
  File "/home/home1/sy189/.local/lib/python3.6/site-packages/urllib3/util/retry.py", line 436, in increment
    raise MaxRetryError(_pool, url, error or ResponseError(cause))
urllib3.exceptions.MaxRetryError: HTTPConnectionPool(host='localhost', port=8888): Max retries exceeded with url: /events (Caused by NewConnectionError('<urllib3.connection.HTTPConnection object at 0x14ba70ea6ba8>: Failed to establish a new connection: [Errno 111] Connection refused',))

During handling of the above exception, another exception occurred:

Traceback (most recent call last):
  File "/home/home1/sy189/.local/lib/python3.6/site-packages/visdom/__init__.py", line 548, in _send
    data=json.dumps(msg),
  File "/home/home1/sy189/.local/lib/python3.6/site-packages/requests/sessions.py", line 581, in post
    return self.request('POST', url, data=data, json=json, **kwargs)
  File "/home/home1/sy189/.local/lib/python3.6/site-packages/requests/sessions.py", line 533, in request
    resp = self.send(prep, **send_kwargs)
  File "/home/home1/sy189/.local/lib/python3.6/site-packages/requests/sessions.py", line 646, in send
    r = adapter.send(request, **kwargs)
  File "/home/home1/sy189/.local/lib/python3.6/site-packages/requests/adapters.py", line 516, in send
    raise ConnectionError(e, request=request)
requests.exceptions.ConnectionError: HTTPConnectionPool(host='localhost', port=8888): Max retries exceeded with url: /events (Caused by NewConnectionError('<urllib3.connection.HTTPConnection object at 0x14ba70ea6ba8>: Failed to establish a new connection: [Errno 111] Connection refused',))
Train loss: 0.044:  12%|█▏        | 16/133 [00:42<02:44,  1.41s/it]Train loss: 0.044:  13%|█▎        | 17/133 [00:42<02:39,  1.37s/it]Traceback (most recent call last):
  File "/home/home1/sy189/.local/lib/python3.6/site-packages/urllib3/connection.py", line 157, in _new_conn
    (self._dns_host, self.port), self.timeout, **extra_kw
  File "/home/home1/sy189/.local/lib/python3.6/site-packages/urllib3/util/connection.py", line 84, in create_connection
    raise err
  File "/home/home1/sy189/.local/lib/python3.6/site-packages/urllib3/util/connection.py", line 74, in create_connection
    sock.connect(sa)
ConnectionRefusedError: [Errno 111] Connection refused

During handling of the above exception, another exception occurred:

Traceback (most recent call last):
  File "/home/home1/sy189/.local/lib/python3.6/site-packages/urllib3/connectionpool.py", line 672, in urlopen
    chunked=chunked,
  File "/home/home1/sy189/.local/lib/python3.6/site-packages/urllib3/connectionpool.py", line 387, in _make_request
    conn.request(method, url, **httplib_request_kw)
  File "/usr/lib/python3.6/http/client.py", line 1254, in request
    self._send_request(method, url, body, headers, encode_chunked)
  File "/usr/lib/python3.6/http/client.py", line 1300, in _send_request
    self.endheaders(body, encode_chunked=encode_chunked)
  File "/usr/lib/python3.6/http/client.py", line 1249, in endheaders
    self._send_output(message_body, encode_chunked=encode_chunked)
  File "/usr/lib/python3.6/http/client.py", line 1036, in _send_output
    self.send(msg)
  File "/usr/lib/python3.6/http/client.py", line 974, in send
    self.connect()
  File "/home/home1/sy189/.local/lib/python3.6/site-packages/urllib3/connection.py", line 184, in connect
    conn = self._new_conn()
  File "/home/home1/sy189/.local/lib/python3.6/site-packages/urllib3/connection.py", line 169, in _new_conn
    self, "Failed to establish a new connection: %s" % e
urllib3.exceptions.NewConnectionError: <urllib3.connection.HTTPConnection object at 0x14ba70ea6d30>: Failed to establish a new connection: [Errno 111] Connection refused

During handling of the above exception, another exception occurred:

Traceback (most recent call last):
  File "/home/home1/sy189/.local/lib/python3.6/site-packages/requests/adapters.py", line 449, in send
    timeout=timeout
  File "/home/home1/sy189/.local/lib/python3.6/site-packages/urllib3/connectionpool.py", line 720, in urlopen
    method, url, error=e, _pool=self, _stacktrace=sys.exc_info()[2]
  File "/home/home1/sy189/.local/lib/python3.6/site-packages/urllib3/util/retry.py", line 436, in increment
    raise MaxRetryError(_pool, url, error or ResponseError(cause))
urllib3.exceptions.MaxRetryError: HTTPConnectionPool(host='localhost', port=8888): Max retries exceeded with url: /events (Caused by NewConnectionError('<urllib3.connection.HTTPConnection object at 0x14ba70ea6d30>: Failed to establish a new connection: [Errno 111] Connection refused',))

During handling of the above exception, another exception occurred:

Traceback (most recent call last):
  File "/home/home1/sy189/.local/lib/python3.6/site-packages/visdom/__init__.py", line 548, in _send
    data=json.dumps(msg),
  File "/home/home1/sy189/.local/lib/python3.6/site-packages/requests/sessions.py", line 581, in post
    return self.request('POST', url, data=data, json=json, **kwargs)
  File "/home/home1/sy189/.local/lib/python3.6/site-packages/requests/sessions.py", line 533, in request
    resp = self.send(prep, **send_kwargs)
  File "/home/home1/sy189/.local/lib/python3.6/site-packages/requests/sessions.py", line 646, in send
    r = adapter.send(request, **kwargs)
  File "/home/home1/sy189/.local/lib/python3.6/site-packages/requests/adapters.py", line 516, in send
    raise ConnectionError(e, request=request)
requests.exceptions.ConnectionError: HTTPConnectionPool(host='localhost', port=8888): Max retries exceeded with url: /events (Caused by NewConnectionError('<urllib3.connection.HTTPConnection object at 0x14ba70ea6d30>: Failed to establish a new connection: [Errno 111] Connection refused',))
Train loss: 0.044:  13%|█▎        | 17/133 [00:44<02:39,  1.37s/it]Train loss: 0.044:  14%|█▎        | 18/133 [00:44<02:44,  1.43s/it]Traceback (most recent call last):
  File "/home/home1/sy189/.local/lib/python3.6/site-packages/urllib3/connection.py", line 157, in _new_conn
    (self._dns_host, self.port), self.timeout, **extra_kw
  File "/home/home1/sy189/.local/lib/python3.6/site-packages/urllib3/util/connection.py", line 84, in create_connection
    raise err
  File "/home/home1/sy189/.local/lib/python3.6/site-packages/urllib3/util/connection.py", line 74, in create_connection
    sock.connect(sa)
ConnectionRefusedError: [Errno 111] Connection refused

During handling of the above exception, another exception occurred:

Traceback (most recent call last):
  File "/home/home1/sy189/.local/lib/python3.6/site-packages/urllib3/connectionpool.py", line 672, in urlopen
    chunked=chunked,
  File "/home/home1/sy189/.local/lib/python3.6/site-packages/urllib3/connectionpool.py", line 387, in _make_request
    conn.request(method, url, **httplib_request_kw)
  File "/usr/lib/python3.6/http/client.py", line 1254, in request
    self._send_request(method, url, body, headers, encode_chunked)
  File "/usr/lib/python3.6/http/client.py", line 1300, in _send_request
    self.endheaders(body, encode_chunked=encode_chunked)
  File "/usr/lib/python3.6/http/client.py", line 1249, in endheaders
    self._send_output(message_body, encode_chunked=encode_chunked)
  File "/usr/lib/python3.6/http/client.py", line 1036, in _send_output
    self.send(msg)
  File "/usr/lib/python3.6/http/client.py", line 974, in send
    self.connect()
  File "/home/home1/sy189/.local/lib/python3.6/site-packages/urllib3/connection.py", line 184, in connect
    conn = self._new_conn()
  File "/home/home1/sy189/.local/lib/python3.6/site-packages/urllib3/connection.py", line 169, in _new_conn
    self, "Failed to establish a new connection: %s" % e
urllib3.exceptions.NewConnectionError: <urllib3.connection.HTTPConnection object at 0x14ba70ea6278>: Failed to establish a new connection: [Errno 111] Connection refused

During handling of the above exception, another exception occurred:

Traceback (most recent call last):
  File "/home/home1/sy189/.local/lib/python3.6/site-packages/requests/adapters.py", line 449, in send
    timeout=timeout
  File "/home/home1/sy189/.local/lib/python3.6/site-packages/urllib3/connectionpool.py", line 720, in urlopen
    method, url, error=e, _pool=self, _stacktrace=sys.exc_info()[2]
  File "/home/home1/sy189/.local/lib/python3.6/site-packages/urllib3/util/retry.py", line 436, in increment
    raise MaxRetryError(_pool, url, error or ResponseError(cause))
urllib3.exceptions.MaxRetryError: HTTPConnectionPool(host='localhost', port=8888): Max retries exceeded with url: /events (Caused by NewConnectionError('<urllib3.connection.HTTPConnection object at 0x14ba70ea6278>: Failed to establish a new connection: [Errno 111] Connection refused',))

During handling of the above exception, another exception occurred:

Traceback (most recent call last):
  File "/home/home1/sy189/.local/lib/python3.6/site-packages/visdom/__init__.py", line 548, in _send
    data=json.dumps(msg),
  File "/home/home1/sy189/.local/lib/python3.6/site-packages/requests/sessions.py", line 581, in post
    return self.request('POST', url, data=data, json=json, **kwargs)
  File "/home/home1/sy189/.local/lib/python3.6/site-packages/requests/sessions.py", line 533, in request
    resp = self.send(prep, **send_kwargs)
  File "/home/home1/sy189/.local/lib/python3.6/site-packages/requests/sessions.py", line 646, in send
    r = adapter.send(request, **kwargs)
  File "/home/home1/sy189/.local/lib/python3.6/site-packages/requests/adapters.py", line 516, in send
    raise ConnectionError(e, request=request)
requests.exceptions.ConnectionError: HTTPConnectionPool(host='localhost', port=8888): Max retries exceeded with url: /events (Caused by NewConnectionError('<urllib3.connection.HTTPConnection object at 0x14ba70ea6278>: Failed to establish a new connection: [Errno 111] Connection refused',))
Train loss: 0.044:  14%|█▎        | 18/133 [00:45<02:44,  1.43s/it]Train loss: 0.044:  14%|█▍        | 19/133 [00:45<02:37,  1.38s/it]Traceback (most recent call last):
  File "/home/home1/sy189/.local/lib/python3.6/site-packages/urllib3/connection.py", line 157, in _new_conn
    (self._dns_host, self.port), self.timeout, **extra_kw
  File "/home/home1/sy189/.local/lib/python3.6/site-packages/urllib3/util/connection.py", line 84, in create_connection
    raise err
  File "/home/home1/sy189/.local/lib/python3.6/site-packages/urllib3/util/connection.py", line 74, in create_connection
    sock.connect(sa)
ConnectionRefusedError: [Errno 111] Connection refused

During handling of the above exception, another exception occurred:

Traceback (most recent call last):
  File "/home/home1/sy189/.local/lib/python3.6/site-packages/urllib3/connectionpool.py", line 672, in urlopen
    chunked=chunked,
  File "/home/home1/sy189/.local/lib/python3.6/site-packages/urllib3/connectionpool.py", line 387, in _make_request
    conn.request(method, url, **httplib_request_kw)
  File "/usr/lib/python3.6/http/client.py", line 1254, in request
    self._send_request(method, url, body, headers, encode_chunked)
  File "/usr/lib/python3.6/http/client.py", line 1300, in _send_request
    self.endheaders(body, encode_chunked=encode_chunked)
  File "/usr/lib/python3.6/http/client.py", line 1249, in endheaders
    self._send_output(message_body, encode_chunked=encode_chunked)
  File "/usr/lib/python3.6/http/client.py", line 1036, in _send_output
    self.send(msg)
  File "/usr/lib/python3.6/http/client.py", line 974, in send
    self.connect()
  File "/home/home1/sy189/.local/lib/python3.6/site-packages/urllib3/connection.py", line 184, in connect
    conn = self._new_conn()
  File "/home/home1/sy189/.local/lib/python3.6/site-packages/urllib3/connection.py", line 169, in _new_conn
    self, "Failed to establish a new connection: %s" % e
urllib3.exceptions.NewConnectionError: <urllib3.connection.HTTPConnection object at 0x14ba70ea6e48>: Failed to establish a new connection: [Errno 111] Connection refused

During handling of the above exception, another exception occurred:

Traceback (most recent call last):
  File "/home/home1/sy189/.local/lib/python3.6/site-packages/requests/adapters.py", line 449, in send
    timeout=timeout
  File "/home/home1/sy189/.local/lib/python3.6/site-packages/urllib3/connectionpool.py", line 720, in urlopen
    method, url, error=e, _pool=self, _stacktrace=sys.exc_info()[2]
  File "/home/home1/sy189/.local/lib/python3.6/site-packages/urllib3/util/retry.py", line 436, in increment
    raise MaxRetryError(_pool, url, error or ResponseError(cause))
urllib3.exceptions.MaxRetryError: HTTPConnectionPool(host='localhost', port=8888): Max retries exceeded with url: /events (Caused by NewConnectionError('<urllib3.connection.HTTPConnection object at 0x14ba70ea6e48>: Failed to establish a new connection: [Errno 111] Connection refused',))

During handling of the above exception, another exception occurred:

Traceback (most recent call last):
  File "/home/home1/sy189/.local/lib/python3.6/site-packages/visdom/__init__.py", line 548, in _send
    data=json.dumps(msg),
  File "/home/home1/sy189/.local/lib/python3.6/site-packages/requests/sessions.py", line 581, in post
    return self.request('POST', url, data=data, json=json, **kwargs)
  File "/home/home1/sy189/.local/lib/python3.6/site-packages/requests/sessions.py", line 533, in request
    resp = self.send(prep, **send_kwargs)
  File "/home/home1/sy189/.local/lib/python3.6/site-packages/requests/sessions.py", line 646, in send
    r = adapter.send(request, **kwargs)
  File "/home/home1/sy189/.local/lib/python3.6/site-packages/requests/adapters.py", line 516, in send
    raise ConnectionError(e, request=request)
requests.exceptions.ConnectionError: HTTPConnectionPool(host='localhost', port=8888): Max retries exceeded with url: /events (Caused by NewConnectionError('<urllib3.connection.HTTPConnection object at 0x14ba70ea6e48>: Failed to establish a new connection: [Errno 111] Connection refused',))
Train loss: 0.044:  14%|█▍        | 19/133 [00:47<02:37,  1.38s/it]Train loss: 0.044:  15%|█▌        | 20/133 [00:47<02:35,  1.38s/it]Traceback (most recent call last):
  File "/home/home1/sy189/.local/lib/python3.6/site-packages/urllib3/connection.py", line 157, in _new_conn
    (self._dns_host, self.port), self.timeout, **extra_kw
  File "/home/home1/sy189/.local/lib/python3.6/site-packages/urllib3/util/connection.py", line 84, in create_connection
    raise err
  File "/home/home1/sy189/.local/lib/python3.6/site-packages/urllib3/util/connection.py", line 74, in create_connection
    sock.connect(sa)
ConnectionRefusedError: [Errno 111] Connection refused

During handling of the above exception, another exception occurred:

Traceback (most recent call last):
  File "/home/home1/sy189/.local/lib/python3.6/site-packages/urllib3/connectionpool.py", line 672, in urlopen
    chunked=chunked,
  File "/home/home1/sy189/.local/lib/python3.6/site-packages/urllib3/connectionpool.py", line 387, in _make_request
    conn.request(method, url, **httplib_request_kw)
  File "/usr/lib/python3.6/http/client.py", line 1254, in request
    self._send_request(method, url, body, headers, encode_chunked)
  File "/usr/lib/python3.6/http/client.py", line 1300, in _send_request
    self.endheaders(body, encode_chunked=encode_chunked)
  File "/usr/lib/python3.6/http/client.py", line 1249, in endheaders
    self._send_output(message_body, encode_chunked=encode_chunked)
  File "/usr/lib/python3.6/http/client.py", line 1036, in _send_output
    self.send(msg)
  File "/usr/lib/python3.6/http/client.py", line 974, in send
    self.connect()
  File "/home/home1/sy189/.local/lib/python3.6/site-packages/urllib3/connection.py", line 184, in connect
    conn = self._new_conn()
  File "/home/home1/sy189/.local/lib/python3.6/site-packages/urllib3/connection.py", line 169, in _new_conn
    self, "Failed to establish a new connection: %s" % e
urllib3.exceptions.NewConnectionError: <urllib3.connection.HTTPConnection object at 0x14ba70e33ac8>: Failed to establish a new connection: [Errno 111] Connection refused

During handling of the above exception, another exception occurred:

Traceback (most recent call last):
  File "/home/home1/sy189/.local/lib/python3.6/site-packages/requests/adapters.py", line 449, in send
    timeout=timeout
  File "/home/home1/sy189/.local/lib/python3.6/site-packages/urllib3/connectionpool.py", line 720, in urlopen
    method, url, error=e, _pool=self, _stacktrace=sys.exc_info()[2]
  File "/home/home1/sy189/.local/lib/python3.6/site-packages/urllib3/util/retry.py", line 436, in increment
    raise MaxRetryError(_pool, url, error or ResponseError(cause))
urllib3.exceptions.MaxRetryError: HTTPConnectionPool(host='localhost', port=8888): Max retries exceeded with url: /events (Caused by NewConnectionError('<urllib3.connection.HTTPConnection object at 0x14ba70e33ac8>: Failed to establish a new connection: [Errno 111] Connection refused',))

During handling of the above exception, another exception occurred:

Traceback (most recent call last):
  File "/home/home1/sy189/.local/lib/python3.6/site-packages/visdom/__init__.py", line 548, in _send
    data=json.dumps(msg),
  File "/home/home1/sy189/.local/lib/python3.6/site-packages/requests/sessions.py", line 581, in post
    return self.request('POST', url, data=data, json=json, **kwargs)
  File "/home/home1/sy189/.local/lib/python3.6/site-packages/requests/sessions.py", line 533, in request
    resp = self.send(prep, **send_kwargs)
  File "/home/home1/sy189/.local/lib/python3.6/site-packages/requests/sessions.py", line 646, in send
    r = adapter.send(request, **kwargs)
  File "/home/home1/sy189/.local/lib/python3.6/site-packages/requests/adapters.py", line 516, in send
    raise ConnectionError(e, request=request)
requests.exceptions.ConnectionError: HTTPConnectionPool(host='localhost', port=8888): Max retries exceeded with url: /events (Caused by NewConnectionError('<urllib3.connection.HTTPConnection object at 0x14ba70e33ac8>: Failed to establish a new connection: [Errno 111] Connection refused',))
Train loss: 0.044:  15%|█▌        | 20/133 [00:48<02:35,  1.38s/it]Train loss: 0.044:  16%|█▌        | 21/133 [00:48<02:32,  1.36s/it]Traceback (most recent call last):
  File "/home/home1/sy189/.local/lib/python3.6/site-packages/urllib3/connection.py", line 157, in _new_conn
    (self._dns_host, self.port), self.timeout, **extra_kw
  File "/home/home1/sy189/.local/lib/python3.6/site-packages/urllib3/util/connection.py", line 84, in create_connection
    raise err
  File "/home/home1/sy189/.local/lib/python3.6/site-packages/urllib3/util/connection.py", line 74, in create_connection
    sock.connect(sa)
ConnectionRefusedError: [Errno 111] Connection refused

During handling of the above exception, another exception occurred:

Traceback (most recent call last):
  File "/home/home1/sy189/.local/lib/python3.6/site-packages/urllib3/connectionpool.py", line 672, in urlopen
    chunked=chunked,
  File "/home/home1/sy189/.local/lib/python3.6/site-packages/urllib3/connectionpool.py", line 387, in _make_request
    conn.request(method, url, **httplib_request_kw)
  File "/usr/lib/python3.6/http/client.py", line 1254, in request
    self._send_request(method, url, body, headers, encode_chunked)
  File "/usr/lib/python3.6/http/client.py", line 1300, in _send_request
    self.endheaders(body, encode_chunked=encode_chunked)
  File "/usr/lib/python3.6/http/client.py", line 1249, in endheaders
    self._send_output(message_body, encode_chunked=encode_chunked)
  File "/usr/lib/python3.6/http/client.py", line 1036, in _send_output
    self.send(msg)
  File "/usr/lib/python3.6/http/client.py", line 974, in send
    self.connect()
  File "/home/home1/sy189/.local/lib/python3.6/site-packages/urllib3/connection.py", line 184, in connect
    conn = self._new_conn()
  File "/home/home1/sy189/.local/lib/python3.6/site-packages/urllib3/connection.py", line 169, in _new_conn
    self, "Failed to establish a new connection: %s" % e
urllib3.exceptions.NewConnectionError: <urllib3.connection.HTTPConnection object at 0x14ba70e334e0>: Failed to establish a new connection: [Errno 111] Connection refused

During handling of the above exception, another exception occurred:

Traceback (most recent call last):
  File "/home/home1/sy189/.local/lib/python3.6/site-packages/requests/adapters.py", line 449, in send
    timeout=timeout
  File "/home/home1/sy189/.local/lib/python3.6/site-packages/urllib3/connectionpool.py", line 720, in urlopen
    method, url, error=e, _pool=self, _stacktrace=sys.exc_info()[2]
  File "/home/home1/sy189/.local/lib/python3.6/site-packages/urllib3/util/retry.py", line 436, in increment
    raise MaxRetryError(_pool, url, error or ResponseError(cause))
urllib3.exceptions.MaxRetryError: HTTPConnectionPool(host='localhost', port=8888): Max retries exceeded with url: /events (Caused by NewConnectionError('<urllib3.connection.HTTPConnection object at 0x14ba70e334e0>: Failed to establish a new connection: [Errno 111] Connection refused',))

During handling of the above exception, another exception occurred:

Traceback (most recent call last):
  File "/home/home1/sy189/.local/lib/python3.6/site-packages/visdom/__init__.py", line 548, in _send
    data=json.dumps(msg),
  File "/home/home1/sy189/.local/lib/python3.6/site-packages/requests/sessions.py", line 581, in post
    return self.request('POST', url, data=data, json=json, **kwargs)
  File "/home/home1/sy189/.local/lib/python3.6/site-packages/requests/sessions.py", line 533, in request
    resp = self.send(prep, **send_kwargs)
  File "/home/home1/sy189/.local/lib/python3.6/site-packages/requests/sessions.py", line 646, in send
    r = adapter.send(request, **kwargs)
  File "/home/home1/sy189/.local/lib/python3.6/site-packages/requests/adapters.py", line 516, in send
    raise ConnectionError(e, request=request)
requests.exceptions.ConnectionError: HTTPConnectionPool(host='localhost', port=8888): Max retries exceeded with url: /events (Caused by NewConnectionError('<urllib3.connection.HTTPConnection object at 0x14ba70e334e0>: Failed to establish a new connection: [Errno 111] Connection refused',))
Train loss: 0.044:  16%|█▌        | 21/133 [00:49<02:32,  1.36s/it]Train loss: 0.044:  17%|█▋        | 22/133 [00:49<02:28,  1.34s/it]Traceback (most recent call last):
  File "/home/home1/sy189/.local/lib/python3.6/site-packages/urllib3/connection.py", line 157, in _new_conn
    (self._dns_host, self.port), self.timeout, **extra_kw
  File "/home/home1/sy189/.local/lib/python3.6/site-packages/urllib3/util/connection.py", line 84, in create_connection
    raise err
  File "/home/home1/sy189/.local/lib/python3.6/site-packages/urllib3/util/connection.py", line 74, in create_connection
    sock.connect(sa)
ConnectionRefusedError: [Errno 111] Connection refused

During handling of the above exception, another exception occurred:

Traceback (most recent call last):
  File "/home/home1/sy189/.local/lib/python3.6/site-packages/urllib3/connectionpool.py", line 672, in urlopen
    chunked=chunked,
  File "/home/home1/sy189/.local/lib/python3.6/site-packages/urllib3/connectionpool.py", line 387, in _make_request
    conn.request(method, url, **httplib_request_kw)
  File "/usr/lib/python3.6/http/client.py", line 1254, in request
    self._send_request(method, url, body, headers, encode_chunked)
  File "/usr/lib/python3.6/http/client.py", line 1300, in _send_request
    self.endheaders(body, encode_chunked=encode_chunked)
  File "/usr/lib/python3.6/http/client.py", line 1249, in endheaders
    self._send_output(message_body, encode_chunked=encode_chunked)
  File "/usr/lib/python3.6/http/client.py", line 1036, in _send_output
    self.send(msg)
  File "/usr/lib/python3.6/http/client.py", line 974, in send
    self.connect()
  File "/home/home1/sy189/.local/lib/python3.6/site-packages/urllib3/connection.py", line 184, in connect
    conn = self._new_conn()
  File "/home/home1/sy189/.local/lib/python3.6/site-packages/urllib3/connection.py", line 169, in _new_conn
    self, "Failed to establish a new connection: %s" % e
urllib3.exceptions.NewConnectionError: <urllib3.connection.HTTPConnection object at 0x14ba70e334e0>: Failed to establish a new connection: [Errno 111] Connection refused

During handling of the above exception, another exception occurred:

Traceback (most recent call last):
  File "/home/home1/sy189/.local/lib/python3.6/site-packages/requests/adapters.py", line 449, in send
    timeout=timeout
  File "/home/home1/sy189/.local/lib/python3.6/site-packages/urllib3/connectionpool.py", line 720, in urlopen
    method, url, error=e, _pool=self, _stacktrace=sys.exc_info()[2]
  File "/home/home1/sy189/.local/lib/python3.6/site-packages/urllib3/util/retry.py", line 436, in increment
    raise MaxRetryError(_pool, url, error or ResponseError(cause))
urllib3.exceptions.MaxRetryError: HTTPConnectionPool(host='localhost', port=8888): Max retries exceeded with url: /events (Caused by NewConnectionError('<urllib3.connection.HTTPConnection object at 0x14ba70e334e0>: Failed to establish a new connection: [Errno 111] Connection refused',))

During handling of the above exception, another exception occurred:

Traceback (most recent call last):
  File "/home/home1/sy189/.local/lib/python3.6/site-packages/visdom/__init__.py", line 548, in _send
    data=json.dumps(msg),
  File "/home/home1/sy189/.local/lib/python3.6/site-packages/requests/sessions.py", line 581, in post
    return self.request('POST', url, data=data, json=json, **kwargs)
  File "/home/home1/sy189/.local/lib/python3.6/site-packages/requests/sessions.py", line 533, in request
    resp = self.send(prep, **send_kwargs)
  File "/home/home1/sy189/.local/lib/python3.6/site-packages/requests/sessions.py", line 646, in send
    r = adapter.send(request, **kwargs)
  File "/home/home1/sy189/.local/lib/python3.6/site-packages/requests/adapters.py", line 516, in send
    raise ConnectionError(e, request=request)
requests.exceptions.ConnectionError: HTTPConnectionPool(host='localhost', port=8888): Max retries exceeded with url: /events (Caused by NewConnectionError('<urllib3.connection.HTTPConnection object at 0x14ba70e334e0>: Failed to establish a new connection: [Errno 111] Connection refused',))
Train loss: 0.044:  17%|█▋        | 22/133 [00:51<02:28,  1.34s/it]Train loss: 0.044:  17%|█▋        | 23/133 [00:51<02:32,  1.39s/it]Traceback (most recent call last):
  File "/home/home1/sy189/.local/lib/python3.6/site-packages/urllib3/connection.py", line 157, in _new_conn
    (self._dns_host, self.port), self.timeout, **extra_kw
  File "/home/home1/sy189/.local/lib/python3.6/site-packages/urllib3/util/connection.py", line 84, in create_connection
    raise err
  File "/home/home1/sy189/.local/lib/python3.6/site-packages/urllib3/util/connection.py", line 74, in create_connection
    sock.connect(sa)
ConnectionRefusedError: [Errno 111] Connection refused

During handling of the above exception, another exception occurred:

Traceback (most recent call last):
  File "/home/home1/sy189/.local/lib/python3.6/site-packages/urllib3/connectionpool.py", line 672, in urlopen
    chunked=chunked,
  File "/home/home1/sy189/.local/lib/python3.6/site-packages/urllib3/connectionpool.py", line 387, in _make_request
    conn.request(method, url, **httplib_request_kw)
  File "/usr/lib/python3.6/http/client.py", line 1254, in request
    self._send_request(method, url, body, headers, encode_chunked)
  File "/usr/lib/python3.6/http/client.py", line 1300, in _send_request
    self.endheaders(body, encode_chunked=encode_chunked)
  File "/usr/lib/python3.6/http/client.py", line 1249, in endheaders
    self._send_output(message_body, encode_chunked=encode_chunked)
  File "/usr/lib/python3.6/http/client.py", line 1036, in _send_output
    self.send(msg)
  File "/usr/lib/python3.6/http/client.py", line 974, in send
    self.connect()
  File "/home/home1/sy189/.local/lib/python3.6/site-packages/urllib3/connection.py", line 184, in connect
    conn = self._new_conn()
  File "/home/home1/sy189/.local/lib/python3.6/site-packages/urllib3/connection.py", line 169, in _new_conn
    self, "Failed to establish a new connection: %s" % e
urllib3.exceptions.NewConnectionError: <urllib3.connection.HTTPConnection object at 0x14ba7076af98>: Failed to establish a new connection: [Errno 111] Connection refused

During handling of the above exception, another exception occurred:

Traceback (most recent call last):
  File "/home/home1/sy189/.local/lib/python3.6/site-packages/requests/adapters.py", line 449, in send
    timeout=timeout
  File "/home/home1/sy189/.local/lib/python3.6/site-packages/urllib3/connectionpool.py", line 720, in urlopen
    method, url, error=e, _pool=self, _stacktrace=sys.exc_info()[2]
  File "/home/home1/sy189/.local/lib/python3.6/site-packages/urllib3/util/retry.py", line 436, in increment
    raise MaxRetryError(_pool, url, error or ResponseError(cause))
urllib3.exceptions.MaxRetryError: HTTPConnectionPool(host='localhost', port=8888): Max retries exceeded with url: /events (Caused by NewConnectionError('<urllib3.connection.HTTPConnection object at 0x14ba7076af98>: Failed to establish a new connection: [Errno 111] Connection refused',))

During handling of the above exception, another exception occurred:

Traceback (most recent call last):
  File "/home/home1/sy189/.local/lib/python3.6/site-packages/visdom/__init__.py", line 548, in _send
    data=json.dumps(msg),
  File "/home/home1/sy189/.local/lib/python3.6/site-packages/requests/sessions.py", line 581, in post
    return self.request('POST', url, data=data, json=json, **kwargs)
  File "/home/home1/sy189/.local/lib/python3.6/site-packages/requests/sessions.py", line 533, in request
    resp = self.send(prep, **send_kwargs)
  File "/home/home1/sy189/.local/lib/python3.6/site-packages/requests/sessions.py", line 646, in send
    r = adapter.send(request, **kwargs)
  File "/home/home1/sy189/.local/lib/python3.6/site-packages/requests/adapters.py", line 516, in send
    raise ConnectionError(e, request=request)
requests.exceptions.ConnectionError: HTTPConnectionPool(host='localhost', port=8888): Max retries exceeded with url: /events (Caused by NewConnectionError('<urllib3.connection.HTTPConnection object at 0x14ba7076af98>: Failed to establish a new connection: [Errno 111] Connection refused',))
Train loss: 0.044:  17%|█▋        | 23/133 [00:52<02:32,  1.39s/it]Train loss: 0.044:  18%|█▊        | 24/133 [00:52<02:29,  1.37s/it]Traceback (most recent call last):
  File "/home/home1/sy189/.local/lib/python3.6/site-packages/urllib3/connection.py", line 157, in _new_conn
    (self._dns_host, self.port), self.timeout, **extra_kw
  File "/home/home1/sy189/.local/lib/python3.6/site-packages/urllib3/util/connection.py", line 84, in create_connection
    raise err
  File "/home/home1/sy189/.local/lib/python3.6/site-packages/urllib3/util/connection.py", line 74, in create_connection
    sock.connect(sa)
ConnectionRefusedError: [Errno 111] Connection refused

During handling of the above exception, another exception occurred:

Traceback (most recent call last):
  File "/home/home1/sy189/.local/lib/python3.6/site-packages/urllib3/connectionpool.py", line 672, in urlopen
    chunked=chunked,
  File "/home/home1/sy189/.local/lib/python3.6/site-packages/urllib3/connectionpool.py", line 387, in _make_request
    conn.request(method, url, **httplib_request_kw)
  File "/usr/lib/python3.6/http/client.py", line 1254, in request
    self._send_request(method, url, body, headers, encode_chunked)
  File "/usr/lib/python3.6/http/client.py", line 1300, in _send_request
    self.endheaders(body, encode_chunked=encode_chunked)
  File "/usr/lib/python3.6/http/client.py", line 1249, in endheaders
    self._send_output(message_body, encode_chunked=encode_chunked)
  File "/usr/lib/python3.6/http/client.py", line 1036, in _send_output
    self.send(msg)
  File "/usr/lib/python3.6/http/client.py", line 974, in send
    self.connect()
  File "/home/home1/sy189/.local/lib/python3.6/site-packages/urllib3/connection.py", line 184, in connect
    conn = self._new_conn()
  File "/home/home1/sy189/.local/lib/python3.6/site-packages/urllib3/connection.py", line 169, in _new_conn
    self, "Failed to establish a new connection: %s" % e
urllib3.exceptions.NewConnectionError: <urllib3.connection.HTTPConnection object at 0x14ba7076ae80>: Failed to establish a new connection: [Errno 111] Connection refused

During handling of the above exception, another exception occurred:

Traceback (most recent call last):
  File "/home/home1/sy189/.local/lib/python3.6/site-packages/requests/adapters.py", line 449, in send
    timeout=timeout
  File "/home/home1/sy189/.local/lib/python3.6/site-packages/urllib3/connectionpool.py", line 720, in urlopen
    method, url, error=e, _pool=self, _stacktrace=sys.exc_info()[2]
  File "/home/home1/sy189/.local/lib/python3.6/site-packages/urllib3/util/retry.py", line 436, in increment
    raise MaxRetryError(_pool, url, error or ResponseError(cause))
urllib3.exceptions.MaxRetryError: HTTPConnectionPool(host='localhost', port=8888): Max retries exceeded with url: /events (Caused by NewConnectionError('<urllib3.connection.HTTPConnection object at 0x14ba7076ae80>: Failed to establish a new connection: [Errno 111] Connection refused',))

During handling of the above exception, another exception occurred:

Traceback (most recent call last):
  File "/home/home1/sy189/.local/lib/python3.6/site-packages/visdom/__init__.py", line 548, in _send
    data=json.dumps(msg),
  File "/home/home1/sy189/.local/lib/python3.6/site-packages/requests/sessions.py", line 581, in post
    return self.request('POST', url, data=data, json=json, **kwargs)
  File "/home/home1/sy189/.local/lib/python3.6/site-packages/requests/sessions.py", line 533, in request
    resp = self.send(prep, **send_kwargs)
  File "/home/home1/sy189/.local/lib/python3.6/site-packages/requests/sessions.py", line 646, in send
    r = adapter.send(request, **kwargs)
  File "/home/home1/sy189/.local/lib/python3.6/site-packages/requests/adapters.py", line 516, in send
    raise ConnectionError(e, request=request)
requests.exceptions.ConnectionError: HTTPConnectionPool(host='localhost', port=8888): Max retries exceeded with url: /events (Caused by NewConnectionError('<urllib3.connection.HTTPConnection object at 0x14ba7076ae80>: Failed to establish a new connection: [Errno 111] Connection refused',))
Train loss: 0.044:  18%|█▊        | 24/133 [00:53<02:29,  1.37s/it]Train loss: 0.044:  19%|█▉        | 25/133 [00:53<02:27,  1.36s/it]Traceback (most recent call last):
  File "/home/home1/sy189/.local/lib/python3.6/site-packages/urllib3/connection.py", line 157, in _new_conn
    (self._dns_host, self.port), self.timeout, **extra_kw
  File "/home/home1/sy189/.local/lib/python3.6/site-packages/urllib3/util/connection.py", line 84, in create_connection
    raise err
  File "/home/home1/sy189/.local/lib/python3.6/site-packages/urllib3/util/connection.py", line 74, in create_connection
    sock.connect(sa)
ConnectionRefusedError: [Errno 111] Connection refused

During handling of the above exception, another exception occurred:

Traceback (most recent call last):
  File "/home/home1/sy189/.local/lib/python3.6/site-packages/urllib3/connectionpool.py", line 672, in urlopen
    chunked=chunked,
  File "/home/home1/sy189/.local/lib/python3.6/site-packages/urllib3/connectionpool.py", line 387, in _make_request
    conn.request(method, url, **httplib_request_kw)
  File "/usr/lib/python3.6/http/client.py", line 1254, in request
    self._send_request(method, url, body, headers, encode_chunked)
  File "/usr/lib/python3.6/http/client.py", line 1300, in _send_request
    self.endheaders(body, encode_chunked=encode_chunked)
  File "/usr/lib/python3.6/http/client.py", line 1249, in endheaders
    self._send_output(message_body, encode_chunked=encode_chunked)
  File "/usr/lib/python3.6/http/client.py", line 1036, in _send_output
    self.send(msg)
  File "/usr/lib/python3.6/http/client.py", line 974, in send
    self.connect()
  File "/home/home1/sy189/.local/lib/python3.6/site-packages/urllib3/connection.py", line 184, in connect
    conn = self._new_conn()
  File "/home/home1/sy189/.local/lib/python3.6/site-packages/urllib3/connection.py", line 169, in _new_conn
    self, "Failed to establish a new connection: %s" % e
urllib3.exceptions.NewConnectionError: <urllib3.connection.HTTPConnection object at 0x14ba70e33c18>: Failed to establish a new connection: [Errno 111] Connection refused

During handling of the above exception, another exception occurred:

Traceback (most recent call last):
  File "/home/home1/sy189/.local/lib/python3.6/site-packages/requests/adapters.py", line 449, in send
    timeout=timeout
  File "/home/home1/sy189/.local/lib/python3.6/site-packages/urllib3/connectionpool.py", line 720, in urlopen
    method, url, error=e, _pool=self, _stacktrace=sys.exc_info()[2]
  File "/home/home1/sy189/.local/lib/python3.6/site-packages/urllib3/util/retry.py", line 436, in increment
    raise MaxRetryError(_pool, url, error or ResponseError(cause))
urllib3.exceptions.MaxRetryError: HTTPConnectionPool(host='localhost', port=8888): Max retries exceeded with url: /events (Caused by NewConnectionError('<urllib3.connection.HTTPConnection object at 0x14ba70e33c18>: Failed to establish a new connection: [Errno 111] Connection refused',))

During handling of the above exception, another exception occurred:

Traceback (most recent call last):
  File "/home/home1/sy189/.local/lib/python3.6/site-packages/visdom/__init__.py", line 548, in _send
    data=json.dumps(msg),
  File "/home/home1/sy189/.local/lib/python3.6/site-packages/requests/sessions.py", line 581, in post
    return self.request('POST', url, data=data, json=json, **kwargs)
  File "/home/home1/sy189/.local/lib/python3.6/site-packages/requests/sessions.py", line 533, in request
    resp = self.send(prep, **send_kwargs)
  File "/home/home1/sy189/.local/lib/python3.6/site-packages/requests/sessions.py", line 646, in send
    r = adapter.send(request, **kwargs)
  File "/home/home1/sy189/.local/lib/python3.6/site-packages/requests/adapters.py", line 516, in send
    raise ConnectionError(e, request=request)
requests.exceptions.ConnectionError: HTTPConnectionPool(host='localhost', port=8888): Max retries exceeded with url: /events (Caused by NewConnectionError('<urllib3.connection.HTTPConnection object at 0x14ba70e33c18>: Failed to establish a new connection: [Errno 111] Connection refused',))
Train loss: 0.044:  19%|█▉        | 25/133 [00:55<02:27,  1.36s/it]Train loss: 0.044:  20%|█▉        | 26/133 [00:55<02:23,  1.34s/it]Traceback (most recent call last):
  File "/home/home1/sy189/.local/lib/python3.6/site-packages/urllib3/connection.py", line 157, in _new_conn
    (self._dns_host, self.port), self.timeout, **extra_kw
  File "/home/home1/sy189/.local/lib/python3.6/site-packages/urllib3/util/connection.py", line 84, in create_connection
    raise err
  File "/home/home1/sy189/.local/lib/python3.6/site-packages/urllib3/util/connection.py", line 74, in create_connection
    sock.connect(sa)
ConnectionRefusedError: [Errno 111] Connection refused

During handling of the above exception, another exception occurred:

Traceback (most recent call last):
  File "/home/home1/sy189/.local/lib/python3.6/site-packages/urllib3/connectionpool.py", line 672, in urlopen
    chunked=chunked,
  File "/home/home1/sy189/.local/lib/python3.6/site-packages/urllib3/connectionpool.py", line 387, in _make_request
    conn.request(method, url, **httplib_request_kw)
  File "/usr/lib/python3.6/http/client.py", line 1254, in request
    self._send_request(method, url, body, headers, encode_chunked)
  File "/usr/lib/python3.6/http/client.py", line 1300, in _send_request
    self.endheaders(body, encode_chunked=encode_chunked)
  File "/usr/lib/python3.6/http/client.py", line 1249, in endheaders
    self._send_output(message_body, encode_chunked=encode_chunked)
  File "/usr/lib/python3.6/http/client.py", line 1036, in _send_output
    self.send(msg)
  File "/usr/lib/python3.6/http/client.py", line 974, in send
    self.connect()
  File "/home/home1/sy189/.local/lib/python3.6/site-packages/urllib3/connection.py", line 184, in connect
    conn = self._new_conn()
  File "/home/home1/sy189/.local/lib/python3.6/site-packages/urllib3/connection.py", line 169, in _new_conn
    self, "Failed to establish a new connection: %s" % e
urllib3.exceptions.NewConnectionError: <urllib3.connection.HTTPConnection object at 0x14ba70e33ac8>: Failed to establish a new connection: [Errno 111] Connection refused

During handling of the above exception, another exception occurred:

Traceback (most recent call last):
  File "/home/home1/sy189/.local/lib/python3.6/site-packages/requests/adapters.py", line 449, in send
    timeout=timeout
  File "/home/home1/sy189/.local/lib/python3.6/site-packages/urllib3/connectionpool.py", line 720, in urlopen
    method, url, error=e, _pool=self, _stacktrace=sys.exc_info()[2]
  File "/home/home1/sy189/.local/lib/python3.6/site-packages/urllib3/util/retry.py", line 436, in increment
    raise MaxRetryError(_pool, url, error or ResponseError(cause))
urllib3.exceptions.MaxRetryError: HTTPConnectionPool(host='localhost', port=8888): Max retries exceeded with url: /events (Caused by NewConnectionError('<urllib3.connection.HTTPConnection object at 0x14ba70e33ac8>: Failed to establish a new connection: [Errno 111] Connection refused',))

During handling of the above exception, another exception occurred:

Traceback (most recent call last):
  File "/home/home1/sy189/.local/lib/python3.6/site-packages/visdom/__init__.py", line 548, in _send
    data=json.dumps(msg),
  File "/home/home1/sy189/.local/lib/python3.6/site-packages/requests/sessions.py", line 581, in post
    return self.request('POST', url, data=data, json=json, **kwargs)
  File "/home/home1/sy189/.local/lib/python3.6/site-packages/requests/sessions.py", line 533, in request
    resp = self.send(prep, **send_kwargs)
  File "/home/home1/sy189/.local/lib/python3.6/site-packages/requests/sessions.py", line 646, in send
    r = adapter.send(request, **kwargs)
  File "/home/home1/sy189/.local/lib/python3.6/site-packages/requests/adapters.py", line 516, in send
    raise ConnectionError(e, request=request)
requests.exceptions.ConnectionError: HTTPConnectionPool(host='localhost', port=8888): Max retries exceeded with url: /events (Caused by NewConnectionError('<urllib3.connection.HTTPConnection object at 0x14ba70e33ac8>: Failed to establish a new connection: [Errno 111] Connection refused',))
Train loss: 0.044:  20%|█▉        | 26/133 [00:56<02:23,  1.34s/it]Train loss: 0.044:  20%|██        | 27/133 [00:56<02:21,  1.34s/it]